2023-02-07 07:58:36,056 django.request ERROR    Internal Server Error: /login/
Traceback (most recent call last):
  File "/home/nurmuhammad/.local/lib/python3.10/site-packages/django/core/handlers/exception.py", line 47, in inner
    response = get_response(request)
  File "/home/nurmuhammad/.local/lib/python3.10/site-packages/django/core/handlers/base.py", line 181, in _get_response
    response = wrapped_callback(request, *callback_args, **callback_kwargs)
TypeError: login() missing 1 required positional argument: 'user'
2023-02-07 07:58:38,457 django.request ERROR    Internal Server Error: /login/
Traceback (most recent call last):
  File "/home/nurmuhammad/.local/lib/python3.10/site-packages/django/core/handlers/exception.py", line 47, in inner
    response = get_response(request)
  File "/home/nurmuhammad/.local/lib/python3.10/site-packages/django/core/handlers/base.py", line 181, in _get_response
    response = wrapped_callback(request, *callback_args, **callback_kwargs)
TypeError: login() missing 1 required positional argument: 'user'
2023-02-07 07:58:39,446 django.request ERROR    Internal Server Error: /login/
Traceback (most recent call last):
  File "/home/nurmuhammad/.local/lib/python3.10/site-packages/django/core/handlers/exception.py", line 47, in inner
    response = get_response(request)
  File "/home/nurmuhammad/.local/lib/python3.10/site-packages/django/core/handlers/base.py", line 181, in _get_response
    response = wrapped_callback(request, *callback_args, **callback_kwargs)
TypeError: login() missing 1 required positional argument: 'user'
2023-02-07 07:58:39,765 django.request ERROR    Internal Server Error: /login/
Traceback (most recent call last):
  File "/home/nurmuhammad/.local/lib/python3.10/site-packages/django/core/handlers/exception.py", line 47, in inner
    response = get_response(request)
  File "/home/nurmuhammad/.local/lib/python3.10/site-packages/django/core/handlers/base.py", line 181, in _get_response
    response = wrapped_callback(request, *callback_args, **callback_kwargs)
TypeError: login() missing 1 required positional argument: 'user'
2023-02-07 07:58:40,075 django.request ERROR    Internal Server Error: /login/
Traceback (most recent call last):
  File "/home/nurmuhammad/.local/lib/python3.10/site-packages/django/core/handlers/exception.py", line 47, in inner
    response = get_response(request)
  File "/home/nurmuhammad/.local/lib/python3.10/site-packages/django/core/handlers/base.py", line 181, in _get_response
    response = wrapped_callback(request, *callback_args, **callback_kwargs)
TypeError: login() missing 1 required positional argument: 'user'
2023-02-07 07:58:44,686 django.request ERROR    Internal Server Error: /login/
Traceback (most recent call last):
  File "/home/nurmuhammad/.local/lib/python3.10/site-packages/django/core/handlers/exception.py", line 47, in inner
    response = get_response(request)
  File "/home/nurmuhammad/.local/lib/python3.10/site-packages/django/core/handlers/base.py", line 181, in _get_response
    response = wrapped_callback(request, *callback_args, **callback_kwargs)
TypeError: login() missing 1 required positional argument: 'user'
2023-02-07 07:59:33,978 django.request ERROR    Internal Server Error: /login/
Traceback (most recent call last):
  File "/home/nurmuhammad/.local/lib/python3.10/site-packages/django/core/handlers/exception.py", line 47, in inner
    response = get_response(request)
  File "/home/nurmuhammad/.local/lib/python3.10/site-packages/django/core/handlers/base.py", line 181, in _get_response
    response = wrapped_callback(request, *callback_args, **callback_kwargs)
TypeError: login() missing 1 required positional argument: 'user'
2023-02-07 08:04:15,849 django.request ERROR    Internal Server Error: /login/
Traceback (most recent call last):
  File "/home/nurmuhammad/.local/lib/python3.10/site-packages/django/core/handlers/exception.py", line 47, in inner
    response = get_response(request)
  File "/home/nurmuhammad/.local/lib/python3.10/site-packages/django/core/handlers/base.py", line 181, in _get_response
    response = wrapped_callback(request, *callback_args, **callback_kwargs)
TypeError: login() missing 1 required positional argument: 'user'
2023-02-07 10:53:53,724 django.request ERROR    Internal Server Error: /login/
Traceback (most recent call last):
  File "/home/nurmuhammad/.local/lib/python3.10/site-packages/django/core/handlers/exception.py", line 47, in inner
    response = get_response(request)
  File "/home/nurmuhammad/.local/lib/python3.10/site-packages/django/core/handlers/base.py", line 181, in _get_response
    response = wrapped_callback(request, *callback_args, **callback_kwargs)
  File "/home/nurmuhammad/e-commerce/backend/src/apps/accounts/views/login.py", line 19, in _wrapped_view
    return view_func(request, *args, **kwargs)
  File "/home/nurmuhammad/e-commerce/backend/src/apps/accounts/views/login.py", line 40, in login
    login(request, user)
  File "/home/nurmuhammad/e-commerce/backend/src/apps/accounts/views/login.py", line 19, in _wrapped_view
    return view_func(request, *args, **kwargs)
TypeError: login() takes 1 positional argument but 2 were given
2023-02-07 10:54:15,265 django.request ERROR    Internal Server Error: /login/
Traceback (most recent call last):
  File "/home/nurmuhammad/.local/lib/python3.10/site-packages/django/core/handlers/exception.py", line 47, in inner
    response = get_response(request)
  File "/home/nurmuhammad/.local/lib/python3.10/site-packages/django/core/handlers/base.py", line 181, in _get_response
    response = wrapped_callback(request, *callback_args, **callback_kwargs)
  File "/home/nurmuhammad/e-commerce/backend/src/apps/accounts/views/login.py", line 19, in _wrapped_view
    return view_func(request, *args, **kwargs)
  File "/home/nurmuhammad/e-commerce/backend/src/apps/accounts/views/login.py", line 40, in login
    login(request, user)
  File "/home/nurmuhammad/e-commerce/backend/src/apps/accounts/views/login.py", line 19, in _wrapped_view
    return view_func(request, *args, **kwargs)
TypeError: login() takes 1 positional argument but 2 were given
2023-02-07 10:57:33,654 django.request ERROR    Internal Server Error: /login/
Traceback (most recent call last):
  File "/home/nurmuhammad/.local/lib/python3.10/site-packages/django/core/handlers/exception.py", line 47, in inner
    response = get_response(request)
  File "/home/nurmuhammad/.local/lib/python3.10/site-packages/django/core/handlers/base.py", line 181, in _get_response
    response = wrapped_callback(request, *callback_args, **callback_kwargs)
  File "/home/nurmuhammad/e-commerce/backend/src/apps/accounts/views/login.py", line 39, in login
    login(request, user)
TypeError: login() takes 1 positional argument but 2 were given
2023-02-07 11:06:08,114 django.request ERROR    Internal Server Error: /login/
Traceback (most recent call last):
  File "/home/nurmuhammad/.local/lib/python3.10/site-packages/django/core/handlers/exception.py", line 47, in inner
    response = get_response(request)
  File "/home/nurmuhammad/.local/lib/python3.10/site-packages/django/core/handlers/base.py", line 181, in _get_response
    response = wrapped_callback(request, *callback_args, **callback_kwargs)
  File "/home/nurmuhammad/e-commerce/backend/src/apps/accounts/views/login.py", line 39, in login
    login(request, user)
TypeError: login() takes 1 positional argument but 2 were given
2023-02-07 11:07:35,534 django.request ERROR    Internal Server Error: /login/
Traceback (most recent call last):
  File "/home/nurmuhammad/.local/lib/python3.10/site-packages/django/core/handlers/exception.py", line 47, in inner
    response = get_response(request)
  File "/home/nurmuhammad/.local/lib/python3.10/site-packages/django/core/handlers/base.py", line 181, in _get_response
    response = wrapped_callback(request, *callback_args, **callback_kwargs)
  File "/home/nurmuhammad/e-commerce/backend/src/apps/accounts/views/login.py", line 19, in _wrapped_view
    return view_func(request, *args, **kwargs)
  File "/home/nurmuhammad/e-commerce/backend/src/apps/accounts/views/login.py", line 39, in login
    login(request, user)
  File "/home/nurmuhammad/e-commerce/backend/src/apps/accounts/views/login.py", line 19, in _wrapped_view
    return view_func(request, *args, **kwargs)
TypeError: login() takes 1 positional argument but 2 were given
2023-02-07 11:09:01,004 django.request ERROR    Internal Server Error: /login/
Traceback (most recent call last):
  File "/home/nurmuhammad/.local/lib/python3.10/site-packages/django/core/handlers/exception.py", line 47, in inner
    response = get_response(request)
  File "/home/nurmuhammad/.local/lib/python3.10/site-packages/django/core/handlers/base.py", line 181, in _get_response
    response = wrapped_callback(request, *callback_args, **callback_kwargs)
  File "/home/nurmuhammad/e-commerce/backend/src/apps/accounts/views/login.py", line 19, in _wrapped_view
    return view_func(request, *args, **kwargs)
  File "/home/nurmuhammad/e-commerce/backend/src/apps/accounts/views/login.py", line 39, in login
    login(request, user)
  File "/home/nurmuhammad/e-commerce/backend/src/apps/accounts/views/login.py", line 19, in _wrapped_view
    return view_func(request, *args, **kwargs)
TypeError: login() takes 1 positional argument but 2 were given
2023-02-11 10:39:21,979 django.request ERROR    Internal Server Error: /
Traceback (most recent call last):
  File "/home/nurmuhammad/.local/lib/python3.10/site-packages/django/template/backends/django.py", line 61, in render
    return self.template.render(context)
  File "/home/nurmuhammad/.local/lib/python3.10/site-packages/django/template/base.py", line 170, in render
    return self._render(context)
  File "/home/nurmuhammad/.local/lib/python3.10/site-packages/django/template/base.py", line 162, in _render
    return self.nodelist.render(context)
  File "/home/nurmuhammad/.local/lib/python3.10/site-packages/django/template/base.py", line 938, in render
    bit = node.render_annotated(context)
  File "/home/nurmuhammad/.local/lib/python3.10/site-packages/django/template/base.py", line 905, in render_annotated
    return self.render(context)
  File "/home/nurmuhammad/.local/lib/python3.10/site-packages/django/template/loader_tags.py", line 150, in render
    return compiled_parent._render(context)
  File "/home/nurmuhammad/.local/lib/python3.10/site-packages/django/template/base.py", line 162, in _render
    return self.nodelist.render(context)
  File "/home/nurmuhammad/.local/lib/python3.10/site-packages/django/template/base.py", line 938, in render
    bit = node.render_annotated(context)
  File "/home/nurmuhammad/.local/lib/python3.10/site-packages/django/template/base.py", line 905, in render_annotated
    return self.render(context)
  File "/home/nurmuhammad/.local/lib/python3.10/site-packages/django/template/loader_tags.py", line 183, in render
    template = context.template.engine.select_template(template_name)
  File "/home/nurmuhammad/.local/lib/python3.10/site-packages/django/template/engine.py", line 180, in select_template
    raise TemplateDoesNotExist(', '.join(not_found))
django.template.exceptions.TemplateDoesNotExist: include/message.html

The above exception was the direct cause of the following exception:

Traceback (most recent call last):
  File "/home/nurmuhammad/.local/lib/python3.10/site-packages/django/core/handlers/exception.py", line 47, in inner
    response = get_response(request)
  File "/home/nurmuhammad/.local/lib/python3.10/site-packages/django/core/handlers/base.py", line 204, in _get_response
    response = response.render()
  File "/home/nurmuhammad/.local/lib/python3.10/site-packages/django/template/response.py", line 105, in render
    self.content = self.rendered_content
  File "/home/nurmuhammad/.local/lib/python3.10/site-packages/django/template/response.py", line 83, in rendered_content
    return template.render(context, self._request)
  File "/home/nurmuhammad/.local/lib/python3.10/site-packages/django/template/backends/django.py", line 63, in render
    reraise(exc, self.backend)
  File "/home/nurmuhammad/.local/lib/python3.10/site-packages/django/template/backends/django.py", line 84, in reraise
    raise new from exc
django.template.exceptions.TemplateDoesNotExist: include/message.html
2023-02-11 12:23:39,769 django.request ERROR    Internal Server Error: /
Traceback (most recent call last):
  File "/home/nurmuhammad/.local/lib/python3.10/site-packages/django/template/backends/django.py", line 61, in render
    return self.template.render(context)
  File "/home/nurmuhammad/.local/lib/python3.10/site-packages/django/template/base.py", line 170, in render
    return self._render(context)
  File "/home/nurmuhammad/.local/lib/python3.10/site-packages/django/template/base.py", line 162, in _render
    return self.nodelist.render(context)
  File "/home/nurmuhammad/.local/lib/python3.10/site-packages/django/template/base.py", line 938, in render
    bit = node.render_annotated(context)
  File "/home/nurmuhammad/.local/lib/python3.10/site-packages/django/template/base.py", line 905, in render_annotated
    return self.render(context)
  File "/home/nurmuhammad/.local/lib/python3.10/site-packages/django/template/loader_tags.py", line 150, in render
    return compiled_parent._render(context)
  File "/home/nurmuhammad/.local/lib/python3.10/site-packages/django/template/base.py", line 162, in _render
    return self.nodelist.render(context)
  File "/home/nurmuhammad/.local/lib/python3.10/site-packages/django/template/base.py", line 938, in render
    bit = node.render_annotated(context)
  File "/home/nurmuhammad/.local/lib/python3.10/site-packages/django/template/base.py", line 905, in render_annotated
    return self.render(context)
  File "/home/nurmuhammad/.local/lib/python3.10/site-packages/django/template/loader_tags.py", line 183, in render
    template = context.template.engine.select_template(template_name)
  File "/home/nurmuhammad/.local/lib/python3.10/site-packages/django/template/engine.py", line 180, in select_template
    raise TemplateDoesNotExist(', '.join(not_found))
django.template.exceptions.TemplateDoesNotExist: include/message.html

The above exception was the direct cause of the following exception:

Traceback (most recent call last):
  File "/home/nurmuhammad/.local/lib/python3.10/site-packages/django/core/handlers/exception.py", line 47, in inner
    response = get_response(request)
  File "/home/nurmuhammad/.local/lib/python3.10/site-packages/django/core/handlers/base.py", line 204, in _get_response
    response = response.render()
  File "/home/nurmuhammad/.local/lib/python3.10/site-packages/django/template/response.py", line 105, in render
    self.content = self.rendered_content
  File "/home/nurmuhammad/.local/lib/python3.10/site-packages/django/template/response.py", line 83, in rendered_content
    return template.render(context, self._request)
  File "/home/nurmuhammad/.local/lib/python3.10/site-packages/django/template/backends/django.py", line 63, in render
    reraise(exc, self.backend)
  File "/home/nurmuhammad/.local/lib/python3.10/site-packages/django/template/backends/django.py", line 84, in reraise
    raise new from exc
django.template.exceptions.TemplateDoesNotExist: include/message.html
2023-02-11 12:23:40,853 django.request ERROR    Internal Server Error: /
Traceback (most recent call last):
  File "/home/nurmuhammad/.local/lib/python3.10/site-packages/django/template/backends/django.py", line 61, in render
    return self.template.render(context)
  File "/home/nurmuhammad/.local/lib/python3.10/site-packages/django/template/base.py", line 170, in render
    return self._render(context)
  File "/home/nurmuhammad/.local/lib/python3.10/site-packages/django/template/base.py", line 162, in _render
    return self.nodelist.render(context)
  File "/home/nurmuhammad/.local/lib/python3.10/site-packages/django/template/base.py", line 938, in render
    bit = node.render_annotated(context)
  File "/home/nurmuhammad/.local/lib/python3.10/site-packages/django/template/base.py", line 905, in render_annotated
    return self.render(context)
  File "/home/nurmuhammad/.local/lib/python3.10/site-packages/django/template/loader_tags.py", line 150, in render
    return compiled_parent._render(context)
  File "/home/nurmuhammad/.local/lib/python3.10/site-packages/django/template/base.py", line 162, in _render
    return self.nodelist.render(context)
  File "/home/nurmuhammad/.local/lib/python3.10/site-packages/django/template/base.py", line 938, in render
    bit = node.render_annotated(context)
  File "/home/nurmuhammad/.local/lib/python3.10/site-packages/django/template/base.py", line 905, in render_annotated
    return self.render(context)
  File "/home/nurmuhammad/.local/lib/python3.10/site-packages/django/template/loader_tags.py", line 183, in render
    template = context.template.engine.select_template(template_name)
  File "/home/nurmuhammad/.local/lib/python3.10/site-packages/django/template/engine.py", line 180, in select_template
    raise TemplateDoesNotExist(', '.join(not_found))
django.template.exceptions.TemplateDoesNotExist: include/message.html

The above exception was the direct cause of the following exception:

Traceback (most recent call last):
  File "/home/nurmuhammad/.local/lib/python3.10/site-packages/django/core/handlers/exception.py", line 47, in inner
    response = get_response(request)
  File "/home/nurmuhammad/.local/lib/python3.10/site-packages/django/core/handlers/base.py", line 204, in _get_response
    response = response.render()
  File "/home/nurmuhammad/.local/lib/python3.10/site-packages/django/template/response.py", line 105, in render
    self.content = self.rendered_content
  File "/home/nurmuhammad/.local/lib/python3.10/site-packages/django/template/response.py", line 83, in rendered_content
    return template.render(context, self._request)
  File "/home/nurmuhammad/.local/lib/python3.10/site-packages/django/template/backends/django.py", line 63, in render
    reraise(exc, self.backend)
  File "/home/nurmuhammad/.local/lib/python3.10/site-packages/django/template/backends/django.py", line 84, in reraise
    raise new from exc
django.template.exceptions.TemplateDoesNotExist: include/message.html
2023-02-11 12:23:43,345 django.request ERROR    Internal Server Error: /
Traceback (most recent call last):
  File "/home/nurmuhammad/.local/lib/python3.10/site-packages/django/template/backends/django.py", line 61, in render
    return self.template.render(context)
  File "/home/nurmuhammad/.local/lib/python3.10/site-packages/django/template/base.py", line 170, in render
    return self._render(context)
  File "/home/nurmuhammad/.local/lib/python3.10/site-packages/django/template/base.py", line 162, in _render
    return self.nodelist.render(context)
  File "/home/nurmuhammad/.local/lib/python3.10/site-packages/django/template/base.py", line 938, in render
    bit = node.render_annotated(context)
  File "/home/nurmuhammad/.local/lib/python3.10/site-packages/django/template/base.py", line 905, in render_annotated
    return self.render(context)
  File "/home/nurmuhammad/.local/lib/python3.10/site-packages/django/template/loader_tags.py", line 150, in render
    return compiled_parent._render(context)
  File "/home/nurmuhammad/.local/lib/python3.10/site-packages/django/template/base.py", line 162, in _render
    return self.nodelist.render(context)
  File "/home/nurmuhammad/.local/lib/python3.10/site-packages/django/template/base.py", line 938, in render
    bit = node.render_annotated(context)
  File "/home/nurmuhammad/.local/lib/python3.10/site-packages/django/template/base.py", line 905, in render_annotated
    return self.render(context)
  File "/home/nurmuhammad/.local/lib/python3.10/site-packages/django/template/loader_tags.py", line 183, in render
    template = context.template.engine.select_template(template_name)
  File "/home/nurmuhammad/.local/lib/python3.10/site-packages/django/template/engine.py", line 180, in select_template
    raise TemplateDoesNotExist(', '.join(not_found))
django.template.exceptions.TemplateDoesNotExist: include/message.html

The above exception was the direct cause of the following exception:

Traceback (most recent call last):
  File "/home/nurmuhammad/.local/lib/python3.10/site-packages/django/core/handlers/exception.py", line 47, in inner
    response = get_response(request)
  File "/home/nurmuhammad/.local/lib/python3.10/site-packages/django/core/handlers/base.py", line 204, in _get_response
    response = response.render()
  File "/home/nurmuhammad/.local/lib/python3.10/site-packages/django/template/response.py", line 105, in render
    self.content = self.rendered_content
  File "/home/nurmuhammad/.local/lib/python3.10/site-packages/django/template/response.py", line 83, in rendered_content
    return template.render(context, self._request)
  File "/home/nurmuhammad/.local/lib/python3.10/site-packages/django/template/backends/django.py", line 63, in render
    reraise(exc, self.backend)
  File "/home/nurmuhammad/.local/lib/python3.10/site-packages/django/template/backends/django.py", line 84, in reraise
    raise new from exc
django.template.exceptions.TemplateDoesNotExist: include/message.html
2023-02-11 12:44:42,453 django.request ERROR    Internal Server Error: /store/cat-2/trainers/
Traceback (most recent call last):
  File "/home/nurmuhammad/.local/lib/python3.10/site-packages/django/core/handlers/exception.py", line 47, in inner
    response = get_response(request)
  File "/home/nurmuhammad/.local/lib/python3.10/site-packages/django/core/handlers/base.py", line 181, in _get_response
    response = wrapped_callback(request, *callback_args, **callback_kwargs)
  File "/home/nurmuhammad/e-commerce/backend/src/apps/store/views/product.py", line 45, in product_detail_view
    variants = ProductVariants.objects_2.colors()
AttributeError: type object 'ProductVariants' has no attribute 'objects_2'
2023-02-11 12:44:44,843 django.request ERROR    Internal Server Error: /store/cat-2/trainers/
Traceback (most recent call last):
  File "/home/nurmuhammad/.local/lib/python3.10/site-packages/django/core/handlers/exception.py", line 47, in inner
    response = get_response(request)
  File "/home/nurmuhammad/.local/lib/python3.10/site-packages/django/core/handlers/base.py", line 181, in _get_response
    response = wrapped_callback(request, *callback_args, **callback_kwargs)
  File "/home/nurmuhammad/e-commerce/backend/src/apps/store/views/product.py", line 45, in product_detail_view
    variants = ProductVariants.objects_2.colors()
AttributeError: type object 'ProductVariants' has no attribute 'objects_2'
2023-02-11 12:44:45,740 django.request ERROR    Internal Server Error: /store/cat-2/trainers/
Traceback (most recent call last):
  File "/home/nurmuhammad/.local/lib/python3.10/site-packages/django/core/handlers/exception.py", line 47, in inner
    response = get_response(request)
  File "/home/nurmuhammad/.local/lib/python3.10/site-packages/django/core/handlers/base.py", line 181, in _get_response
    response = wrapped_callback(request, *callback_args, **callback_kwargs)
  File "/home/nurmuhammad/e-commerce/backend/src/apps/store/views/product.py", line 45, in product_detail_view
    variants = ProductVariants.objects_2.colors()
AttributeError: type object 'ProductVariants' has no attribute 'objects_2'
2023-02-11 12:44:46,100 django.request ERROR    Internal Server Error: /store/cat-2/trainers/
Traceback (most recent call last):
  File "/home/nurmuhammad/.local/lib/python3.10/site-packages/django/core/handlers/exception.py", line 47, in inner
    response = get_response(request)
  File "/home/nurmuhammad/.local/lib/python3.10/site-packages/django/core/handlers/base.py", line 181, in _get_response
    response = wrapped_callback(request, *callback_args, **callback_kwargs)
  File "/home/nurmuhammad/e-commerce/backend/src/apps/store/views/product.py", line 45, in product_detail_view
    variants = ProductVariants.objects_2.colors()
AttributeError: type object 'ProductVariants' has no attribute 'objects_2'
2023-02-11 12:45:26,764 django.request ERROR    Internal Server Error: /store/cat-2/trainers/
Traceback (most recent call last):
  File "/home/nurmuhammad/.local/lib/python3.10/site-packages/django/core/handlers/exception.py", line 47, in inner
    response = get_response(request)
  File "/home/nurmuhammad/.local/lib/python3.10/site-packages/django/core/handlers/base.py", line 181, in _get_response
    response = wrapped_callback(request, *callback_args, **callback_kwargs)
  File "/home/nurmuhammad/e-commerce/backend/src/apps/store/views/product.py", line 45, in product_detail_view
    variants = ProductVariants.object_2.colors()
AttributeError: 'ProductVariantsManager' object has no attribute 'colors'
2023-02-11 12:45:28,781 django.request ERROR    Internal Server Error: /store/cat-2/trainers/
Traceback (most recent call last):
  File "/home/nurmuhammad/.local/lib/python3.10/site-packages/django/core/handlers/exception.py", line 47, in inner
    response = get_response(request)
  File "/home/nurmuhammad/.local/lib/python3.10/site-packages/django/core/handlers/base.py", line 181, in _get_response
    response = wrapped_callback(request, *callback_args, **callback_kwargs)
  File "/home/nurmuhammad/e-commerce/backend/src/apps/store/views/product.py", line 45, in product_detail_view
    variants = ProductVariants.object_2.colors()
AttributeError: 'ProductVariantsManager' object has no attribute 'colors'
2023-02-11 12:45:29,151 django.request ERROR    Internal Server Error: /store/cat-2/trainers/
Traceback (most recent call last):
  File "/home/nurmuhammad/.local/lib/python3.10/site-packages/django/core/handlers/exception.py", line 47, in inner
    response = get_response(request)
  File "/home/nurmuhammad/.local/lib/python3.10/site-packages/django/core/handlers/base.py", line 181, in _get_response
    response = wrapped_callback(request, *callback_args, **callback_kwargs)
  File "/home/nurmuhammad/e-commerce/backend/src/apps/store/views/product.py", line 45, in product_detail_view
    variants = ProductVariants.object_2.colors()
AttributeError: 'ProductVariantsManager' object has no attribute 'colors'
2023-02-11 12:45:29,658 django.request ERROR    Internal Server Error: /store/cat-2/trainers/
Traceback (most recent call last):
  File "/home/nurmuhammad/.local/lib/python3.10/site-packages/django/core/handlers/exception.py", line 47, in inner
    response = get_response(request)
  File "/home/nurmuhammad/.local/lib/python3.10/site-packages/django/core/handlers/base.py", line 181, in _get_response
    response = wrapped_callback(request, *callback_args, **callback_kwargs)
  File "/home/nurmuhammad/e-commerce/backend/src/apps/store/views/product.py", line 45, in product_detail_view
    variants = ProductVariants.object_2.colors()
AttributeError: 'ProductVariantsManager' object has no attribute 'colors'
2023-02-11 12:45:38,658 django.request ERROR    Internal Server Error: /store/cat-2/trainers/
Traceback (most recent call last):
  File "/home/nurmuhammad/.local/lib/python3.10/site-packages/django/core/handlers/exception.py", line 47, in inner
    response = get_response(request)
  File "/home/nurmuhammad/.local/lib/python3.10/site-packages/django/core/handlers/base.py", line 181, in _get_response
    response = wrapped_callback(request, *callback_args, **callback_kwargs)
  File "/home/nurmuhammad/e-commerce/backend/src/apps/store/views/product.py", line 45, in product_detail_view
    variants = ProductVariants.object_2.colors()
AttributeError: 'ProductVariantsManager' object has no attribute 'colors'
2023-02-11 12:45:41,153 django.request ERROR    Internal Server Error: /store/cat-2/trainers/
Traceback (most recent call last):
  File "/home/nurmuhammad/.local/lib/python3.10/site-packages/django/core/handlers/exception.py", line 47, in inner
    response = get_response(request)
  File "/home/nurmuhammad/.local/lib/python3.10/site-packages/django/core/handlers/base.py", line 181, in _get_response
    response = wrapped_callback(request, *callback_args, **callback_kwargs)
  File "/home/nurmuhammad/e-commerce/backend/src/apps/store/views/product.py", line 45, in product_detail_view
    variants = ProductVariants.object_2.colors()
AttributeError: 'ProductVariantsManager' object has no attribute 'colors'
2023-02-11 18:22:57,303 django.request ERROR    Internal Server Error: /store/cat-2/trainers/
Traceback (most recent call last):
  File "/home/nurmuhammad/.local/lib/python3.10/site-packages/django/core/handlers/exception.py", line 47, in inner
    response = get_response(request)
  File "/home/nurmuhammad/.local/lib/python3.10/site-packages/django/core/handlers/base.py", line 181, in _get_response
    response = wrapped_callback(request, *callback_args, **callback_kwargs)
  File "/home/nurmuhammad/e-commerce/backend/src/apps/store/views/product.py", line 45, in product_detail_view
    variants = ProductVariants.object_2.colors()
AttributeError: type object 'ProductVariants' has no attribute 'object_2'
2023-02-11 18:23:00,115 django.request ERROR    Internal Server Error: /store/cat-2/trainers/
Traceback (most recent call last):
  File "/home/nurmuhammad/.local/lib/python3.10/site-packages/django/core/handlers/exception.py", line 47, in inner
    response = get_response(request)
  File "/home/nurmuhammad/.local/lib/python3.10/site-packages/django/core/handlers/base.py", line 181, in _get_response
    response = wrapped_callback(request, *callback_args, **callback_kwargs)
  File "/home/nurmuhammad/e-commerce/backend/src/apps/store/views/product.py", line 45, in product_detail_view
    variants = ProductVariants.object_2.colors()
AttributeError: type object 'ProductVariants' has no attribute 'object_2'
2023-02-11 18:23:01,146 django.request ERROR    Internal Server Error: /store/cat-2/trainers/
Traceback (most recent call last):
  File "/home/nurmuhammad/.local/lib/python3.10/site-packages/django/core/handlers/exception.py", line 47, in inner
    response = get_response(request)
  File "/home/nurmuhammad/.local/lib/python3.10/site-packages/django/core/handlers/base.py", line 181, in _get_response
    response = wrapped_callback(request, *callback_args, **callback_kwargs)
  File "/home/nurmuhammad/e-commerce/backend/src/apps/store/views/product.py", line 45, in product_detail_view
    variants = ProductVariants.object_2.colors()
AttributeError: type object 'ProductVariants' has no attribute 'object_2'
2023-02-11 18:23:01,443 django.request ERROR    Internal Server Error: /store/cat-2/trainers/
Traceback (most recent call last):
  File "/home/nurmuhammad/.local/lib/python3.10/site-packages/django/core/handlers/exception.py", line 47, in inner
    response = get_response(request)
  File "/home/nurmuhammad/.local/lib/python3.10/site-packages/django/core/handlers/base.py", line 181, in _get_response
    response = wrapped_callback(request, *callback_args, **callback_kwargs)
  File "/home/nurmuhammad/e-commerce/backend/src/apps/store/views/product.py", line 45, in product_detail_view
    variants = ProductVariants.object_2.colors()
AttributeError: type object 'ProductVariants' has no attribute 'object_2'
2023-02-11 18:23:01,625 django.request ERROR    Internal Server Error: /store/cat-2/trainers/
Traceback (most recent call last):
  File "/home/nurmuhammad/.local/lib/python3.10/site-packages/django/core/handlers/exception.py", line 47, in inner
    response = get_response(request)
  File "/home/nurmuhammad/.local/lib/python3.10/site-packages/django/core/handlers/base.py", line 181, in _get_response
    response = wrapped_callback(request, *callback_args, **callback_kwargs)
  File "/home/nurmuhammad/e-commerce/backend/src/apps/store/views/product.py", line 45, in product_detail_view
    variants = ProductVariants.object_2.colors()
AttributeError: type object 'ProductVariants' has no attribute 'object_2'
2023-02-11 18:23:01,937 django.request ERROR    Internal Server Error: /store/cat-2/trainers/
Traceback (most recent call last):
  File "/home/nurmuhammad/.local/lib/python3.10/site-packages/django/core/handlers/exception.py", line 47, in inner
    response = get_response(request)
  File "/home/nurmuhammad/.local/lib/python3.10/site-packages/django/core/handlers/base.py", line 181, in _get_response
    response = wrapped_callback(request, *callback_args, **callback_kwargs)
  File "/home/nurmuhammad/e-commerce/backend/src/apps/store/views/product.py", line 45, in product_detail_view
    variants = ProductVariants.object_2.colors()
AttributeError: type object 'ProductVariants' has no attribute 'object_2'
2023-02-11 18:23:02,260 django.request ERROR    Internal Server Error: /store/cat-2/trainers/
Traceback (most recent call last):
  File "/home/nurmuhammad/.local/lib/python3.10/site-packages/django/core/handlers/exception.py", line 47, in inner
    response = get_response(request)
  File "/home/nurmuhammad/.local/lib/python3.10/site-packages/django/core/handlers/base.py", line 181, in _get_response
    response = wrapped_callback(request, *callback_args, **callback_kwargs)
  File "/home/nurmuhammad/e-commerce/backend/src/apps/store/views/product.py", line 45, in product_detail_view
    variants = ProductVariants.object_2.colors()
AttributeError: type object 'ProductVariants' has no attribute 'object_2'
2023-02-11 18:23:02,584 django.request ERROR    Internal Server Error: /store/cat-2/trainers/
Traceback (most recent call last):
  File "/home/nurmuhammad/.local/lib/python3.10/site-packages/django/core/handlers/exception.py", line 47, in inner
    response = get_response(request)
  File "/home/nurmuhammad/.local/lib/python3.10/site-packages/django/core/handlers/base.py", line 181, in _get_response
    response = wrapped_callback(request, *callback_args, **callback_kwargs)
  File "/home/nurmuhammad/e-commerce/backend/src/apps/store/views/product.py", line 45, in product_detail_view
    variants = ProductVariants.object_2.colors()
AttributeError: type object 'ProductVariants' has no attribute 'object_2'
2023-02-11 18:23:02,909 django.request ERROR    Internal Server Error: /store/cat-2/trainers/
Traceback (most recent call last):
  File "/home/nurmuhammad/.local/lib/python3.10/site-packages/django/core/handlers/exception.py", line 47, in inner
    response = get_response(request)
  File "/home/nurmuhammad/.local/lib/python3.10/site-packages/django/core/handlers/base.py", line 181, in _get_response
    response = wrapped_callback(request, *callback_args, **callback_kwargs)
  File "/home/nurmuhammad/e-commerce/backend/src/apps/store/views/product.py", line 45, in product_detail_view
    variants = ProductVariants.object_2.colors()
AttributeError: type object 'ProductVariants' has no attribute 'object_2'
2023-02-11 18:23:03,227 django.request ERROR    Internal Server Error: /store/cat-2/trainers/
Traceback (most recent call last):
  File "/home/nurmuhammad/.local/lib/python3.10/site-packages/django/core/handlers/exception.py", line 47, in inner
    response = get_response(request)
  File "/home/nurmuhammad/.local/lib/python3.10/site-packages/django/core/handlers/base.py", line 181, in _get_response
    response = wrapped_callback(request, *callback_args, **callback_kwargs)
  File "/home/nurmuhammad/e-commerce/backend/src/apps/store/views/product.py", line 45, in product_detail_view
    variants = ProductVariants.object_2.colors()
AttributeError: type object 'ProductVariants' has no attribute 'object_2'
2023-02-11 18:23:03,517 django.request ERROR    Internal Server Error: /store/cat-2/trainers/
Traceback (most recent call last):
  File "/home/nurmuhammad/.local/lib/python3.10/site-packages/django/core/handlers/exception.py", line 47, in inner
    response = get_response(request)
  File "/home/nurmuhammad/.local/lib/python3.10/site-packages/django/core/handlers/base.py", line 181, in _get_response
    response = wrapped_callback(request, *callback_args, **callback_kwargs)
  File "/home/nurmuhammad/e-commerce/backend/src/apps/store/views/product.py", line 45, in product_detail_view
    variants = ProductVariants.object_2.colors()
AttributeError: type object 'ProductVariants' has no attribute 'object_2'
2023-02-11 18:23:03,812 django.request ERROR    Internal Server Error: /store/cat-2/trainers/
Traceback (most recent call last):
  File "/home/nurmuhammad/.local/lib/python3.10/site-packages/django/core/handlers/exception.py", line 47, in inner
    response = get_response(request)
  File "/home/nurmuhammad/.local/lib/python3.10/site-packages/django/core/handlers/base.py", line 181, in _get_response
    response = wrapped_callback(request, *callback_args, **callback_kwargs)
  File "/home/nurmuhammad/e-commerce/backend/src/apps/store/views/product.py", line 45, in product_detail_view
    variants = ProductVariants.object_2.colors()
AttributeError: type object 'ProductVariants' has no attribute 'object_2'
2023-02-11 18:25:35,747 django.request ERROR    Internal Server Error: /store/cat-2/trainers/
Traceback (most recent call last):
  File "/home/nurmuhammad/.local/lib/python3.10/site-packages/django/urls/base.py", line 71, in reverse
    extra, resolver = resolver.namespace_dict[ns]
KeyError: 'cart'

During handling of the above exception, another exception occurred:

Traceback (most recent call last):
  File "/home/nurmuhammad/.local/lib/python3.10/site-packages/django/core/handlers/exception.py", line 47, in inner
    response = get_response(request)
  File "/home/nurmuhammad/.local/lib/python3.10/site-packages/django/core/handlers/base.py", line 181, in _get_response
    response = wrapped_callback(request, *callback_args, **callback_kwargs)
  File "/home/nurmuhammad/e-commerce/backend/src/apps/store/views/product.py", line 51, in product_detail_view
    return render(request, "store/product_detail.html", context)
  File "/home/nurmuhammad/.local/lib/python3.10/site-packages/django/shortcuts.py", line 19, in render
    content = loader.render_to_string(template_name, context, request, using=using)
  File "/home/nurmuhammad/.local/lib/python3.10/site-packages/django/template/loader.py", line 62, in render_to_string
    return template.render(context, request)
  File "/home/nurmuhammad/.local/lib/python3.10/site-packages/django/template/backends/django.py", line 61, in render
    return self.template.render(context)
  File "/home/nurmuhammad/.local/lib/python3.10/site-packages/django/template/base.py", line 170, in render
    return self._render(context)
  File "/home/nurmuhammad/.local/lib/python3.10/site-packages/django/template/base.py", line 162, in _render
    return self.nodelist.render(context)
  File "/home/nurmuhammad/.local/lib/python3.10/site-packages/django/template/base.py", line 938, in render
    bit = node.render_annotated(context)
  File "/home/nurmuhammad/.local/lib/python3.10/site-packages/django/template/base.py", line 905, in render_annotated
    return self.render(context)
  File "/home/nurmuhammad/.local/lib/python3.10/site-packages/django/template/loader_tags.py", line 150, in render
    return compiled_parent._render(context)
  File "/home/nurmuhammad/.local/lib/python3.10/site-packages/django/template/base.py", line 162, in _render
    return self.nodelist.render(context)
  File "/home/nurmuhammad/.local/lib/python3.10/site-packages/django/template/base.py", line 938, in render
    bit = node.render_annotated(context)
  File "/home/nurmuhammad/.local/lib/python3.10/site-packages/django/template/base.py", line 905, in render_annotated
    return self.render(context)
  File "/home/nurmuhammad/.local/lib/python3.10/site-packages/django/template/loader_tags.py", line 62, in render
    result = block.nodelist.render(context)
  File "/home/nurmuhammad/.local/lib/python3.10/site-packages/django/template/base.py", line 938, in render
    bit = node.render_annotated(context)
  File "/home/nurmuhammad/.local/lib/python3.10/site-packages/django/template/base.py", line 905, in render_annotated
    return self.render(context)
  File "/home/nurmuhammad/.local/lib/python3.10/site-packages/django/template/defaulttags.py", line 449, in render
    url = reverse(view_name, args=args, kwargs=kwargs, current_app=current_app)
  File "/home/nurmuhammad/.local/lib/python3.10/site-packages/django/urls/base.py", line 82, in reverse
    raise NoReverseMatch("%s is not a registered namespace" % key)
django.urls.exceptions.NoReverseMatch: 'cart' is not a registered namespace
2023-02-11 18:25:38,061 django.request ERROR    Internal Server Error: /store/cat-2/trainers/
Traceback (most recent call last):
  File "/home/nurmuhammad/.local/lib/python3.10/site-packages/django/urls/base.py", line 71, in reverse
    extra, resolver = resolver.namespace_dict[ns]
KeyError: 'cart'

During handling of the above exception, another exception occurred:

Traceback (most recent call last):
  File "/home/nurmuhammad/.local/lib/python3.10/site-packages/django/core/handlers/exception.py", line 47, in inner
    response = get_response(request)
  File "/home/nurmuhammad/.local/lib/python3.10/site-packages/django/core/handlers/base.py", line 181, in _get_response
    response = wrapped_callback(request, *callback_args, **callback_kwargs)
  File "/home/nurmuhammad/e-commerce/backend/src/apps/store/views/product.py", line 51, in product_detail_view
    return render(request, "store/product_detail.html", context)
  File "/home/nurmuhammad/.local/lib/python3.10/site-packages/django/shortcuts.py", line 19, in render
    content = loader.render_to_string(template_name, context, request, using=using)
  File "/home/nurmuhammad/.local/lib/python3.10/site-packages/django/template/loader.py", line 62, in render_to_string
    return template.render(context, request)
  File "/home/nurmuhammad/.local/lib/python3.10/site-packages/django/template/backends/django.py", line 61, in render
    return self.template.render(context)
  File "/home/nurmuhammad/.local/lib/python3.10/site-packages/django/template/base.py", line 170, in render
    return self._render(context)
  File "/home/nurmuhammad/.local/lib/python3.10/site-packages/django/template/base.py", line 162, in _render
    return self.nodelist.render(context)
  File "/home/nurmuhammad/.local/lib/python3.10/site-packages/django/template/base.py", line 938, in render
    bit = node.render_annotated(context)
  File "/home/nurmuhammad/.local/lib/python3.10/site-packages/django/template/base.py", line 905, in render_annotated
    return self.render(context)
  File "/home/nurmuhammad/.local/lib/python3.10/site-packages/django/template/loader_tags.py", line 150, in render
    return compiled_parent._render(context)
  File "/home/nurmuhammad/.local/lib/python3.10/site-packages/django/template/base.py", line 162, in _render
    return self.nodelist.render(context)
  File "/home/nurmuhammad/.local/lib/python3.10/site-packages/django/template/base.py", line 938, in render
    bit = node.render_annotated(context)
  File "/home/nurmuhammad/.local/lib/python3.10/site-packages/django/template/base.py", line 905, in render_annotated
    return self.render(context)
  File "/home/nurmuhammad/.local/lib/python3.10/site-packages/django/template/loader_tags.py", line 62, in render
    result = block.nodelist.render(context)
  File "/home/nurmuhammad/.local/lib/python3.10/site-packages/django/template/base.py", line 938, in render
    bit = node.render_annotated(context)
  File "/home/nurmuhammad/.local/lib/python3.10/site-packages/django/template/base.py", line 905, in render_annotated
    return self.render(context)
  File "/home/nurmuhammad/.local/lib/python3.10/site-packages/django/template/defaulttags.py", line 449, in render
    url = reverse(view_name, args=args, kwargs=kwargs, current_app=current_app)
  File "/home/nurmuhammad/.local/lib/python3.10/site-packages/django/urls/base.py", line 82, in reverse
    raise NoReverseMatch("%s is not a registered namespace" % key)
django.urls.exceptions.NoReverseMatch: 'cart' is not a registered namespace
2023-02-11 18:27:27,170 django.request ERROR    Internal Server Error: /store/cat-2/trainers/
Traceback (most recent call last):
  File "/home/nurmuhammad/.local/lib/python3.10/site-packages/django/urls/base.py", line 71, in reverse
    extra, resolver = resolver.namespace_dict[ns]
KeyError: 'cart'

During handling of the above exception, another exception occurred:

Traceback (most recent call last):
  File "/home/nurmuhammad/.local/lib/python3.10/site-packages/django/core/handlers/exception.py", line 47, in inner
    response = get_response(request)
  File "/home/nurmuhammad/.local/lib/python3.10/site-packages/django/core/handlers/base.py", line 181, in _get_response
    response = wrapped_callback(request, *callback_args, **callback_kwargs)
  File "/home/nurmuhammad/e-commerce/backend/src/apps/store/views/product.py", line 51, in product_detail_view
    return render(request, "store/product_detail.html", context)
  File "/home/nurmuhammad/.local/lib/python3.10/site-packages/django/shortcuts.py", line 19, in render
    content = loader.render_to_string(template_name, context, request, using=using)
  File "/home/nurmuhammad/.local/lib/python3.10/site-packages/django/template/loader.py", line 62, in render_to_string
    return template.render(context, request)
  File "/home/nurmuhammad/.local/lib/python3.10/site-packages/django/template/backends/django.py", line 61, in render
    return self.template.render(context)
  File "/home/nurmuhammad/.local/lib/python3.10/site-packages/django/template/base.py", line 170, in render
    return self._render(context)
  File "/home/nurmuhammad/.local/lib/python3.10/site-packages/django/template/base.py", line 162, in _render
    return self.nodelist.render(context)
  File "/home/nurmuhammad/.local/lib/python3.10/site-packages/django/template/base.py", line 938, in render
    bit = node.render_annotated(context)
  File "/home/nurmuhammad/.local/lib/python3.10/site-packages/django/template/base.py", line 905, in render_annotated
    return self.render(context)
  File "/home/nurmuhammad/.local/lib/python3.10/site-packages/django/template/loader_tags.py", line 150, in render
    return compiled_parent._render(context)
  File "/home/nurmuhammad/.local/lib/python3.10/site-packages/django/template/base.py", line 162, in _render
    return self.nodelist.render(context)
  File "/home/nurmuhammad/.local/lib/python3.10/site-packages/django/template/base.py", line 938, in render
    bit = node.render_annotated(context)
  File "/home/nurmuhammad/.local/lib/python3.10/site-packages/django/template/base.py", line 905, in render_annotated
    return self.render(context)
  File "/home/nurmuhammad/.local/lib/python3.10/site-packages/django/template/loader_tags.py", line 62, in render
    result = block.nodelist.render(context)
  File "/home/nurmuhammad/.local/lib/python3.10/site-packages/django/template/base.py", line 938, in render
    bit = node.render_annotated(context)
  File "/home/nurmuhammad/.local/lib/python3.10/site-packages/django/template/base.py", line 905, in render_annotated
    return self.render(context)
  File "/home/nurmuhammad/.local/lib/python3.10/site-packages/django/template/defaulttags.py", line 449, in render
    url = reverse(view_name, args=args, kwargs=kwargs, current_app=current_app)
  File "/home/nurmuhammad/.local/lib/python3.10/site-packages/django/urls/base.py", line 82, in reverse
    raise NoReverseMatch("%s is not a registered namespace" % key)
django.urls.exceptions.NoReverseMatch: 'cart' is not a registered namespace
2023-02-11 18:28:50,521 django.request ERROR    Internal Server Error: /store/cat-2/trainers/
Traceback (most recent call last):
  File "/home/nurmuhammad/.local/lib/python3.10/site-packages/django/urls/base.py", line 71, in reverse
    extra, resolver = resolver.namespace_dict[ns]
KeyError: 'cart'

During handling of the above exception, another exception occurred:

Traceback (most recent call last):
  File "/home/nurmuhammad/.local/lib/python3.10/site-packages/django/core/handlers/exception.py", line 47, in inner
    response = get_response(request)
  File "/home/nurmuhammad/.local/lib/python3.10/site-packages/django/core/handlers/base.py", line 181, in _get_response
    response = wrapped_callback(request, *callback_args, **callback_kwargs)
  File "/home/nurmuhammad/e-commerce/backend/src/apps/store/views/product.py", line 51, in product_detail_view
    return render(request, "store/product_detail.html", context)
  File "/home/nurmuhammad/.local/lib/python3.10/site-packages/django/shortcuts.py", line 19, in render
    content = loader.render_to_string(template_name, context, request, using=using)
  File "/home/nurmuhammad/.local/lib/python3.10/site-packages/django/template/loader.py", line 62, in render_to_string
    return template.render(context, request)
  File "/home/nurmuhammad/.local/lib/python3.10/site-packages/django/template/backends/django.py", line 61, in render
    return self.template.render(context)
  File "/home/nurmuhammad/.local/lib/python3.10/site-packages/django/template/base.py", line 170, in render
    return self._render(context)
  File "/home/nurmuhammad/.local/lib/python3.10/site-packages/django/template/base.py", line 162, in _render
    return self.nodelist.render(context)
  File "/home/nurmuhammad/.local/lib/python3.10/site-packages/django/template/base.py", line 938, in render
    bit = node.render_annotated(context)
  File "/home/nurmuhammad/.local/lib/python3.10/site-packages/django/template/base.py", line 905, in render_annotated
    return self.render(context)
  File "/home/nurmuhammad/.local/lib/python3.10/site-packages/django/template/loader_tags.py", line 150, in render
    return compiled_parent._render(context)
  File "/home/nurmuhammad/.local/lib/python3.10/site-packages/django/template/base.py", line 162, in _render
    return self.nodelist.render(context)
  File "/home/nurmuhammad/.local/lib/python3.10/site-packages/django/template/base.py", line 938, in render
    bit = node.render_annotated(context)
  File "/home/nurmuhammad/.local/lib/python3.10/site-packages/django/template/base.py", line 905, in render_annotated
    return self.render(context)
  File "/home/nurmuhammad/.local/lib/python3.10/site-packages/django/template/loader_tags.py", line 62, in render
    result = block.nodelist.render(context)
  File "/home/nurmuhammad/.local/lib/python3.10/site-packages/django/template/base.py", line 938, in render
    bit = node.render_annotated(context)
  File "/home/nurmuhammad/.local/lib/python3.10/site-packages/django/template/base.py", line 905, in render_annotated
    return self.render(context)
  File "/home/nurmuhammad/.local/lib/python3.10/site-packages/django/template/defaulttags.py", line 449, in render
    url = reverse(view_name, args=args, kwargs=kwargs, current_app=current_app)
  File "/home/nurmuhammad/.local/lib/python3.10/site-packages/django/urls/base.py", line 82, in reverse
    raise NoReverseMatch("%s is not a registered namespace" % key)
django.urls.exceptions.NoReverseMatch: 'cart' is not a registered namespace
2023-02-11 18:33:27,331 django.request ERROR    Internal Server Error: /store/cat-2/trainers/
Traceback (most recent call last):
  File "/home/nurmuhammad/.local/lib/python3.10/site-packages/django/urls/base.py", line 71, in reverse
    extra, resolver = resolver.namespace_dict[ns]
KeyError: 'cart'

During handling of the above exception, another exception occurred:

Traceback (most recent call last):
  File "/home/nurmuhammad/.local/lib/python3.10/site-packages/django/core/handlers/exception.py", line 47, in inner
    response = get_response(request)
  File "/home/nurmuhammad/.local/lib/python3.10/site-packages/django/core/handlers/base.py", line 181, in _get_response
    response = wrapped_callback(request, *callback_args, **callback_kwargs)
  File "/home/nurmuhammad/e-commerce/backend/src/apps/store/views/product.py", line 51, in product_detail_view
    return render(request, "store/product_detail.html", context)
  File "/home/nurmuhammad/.local/lib/python3.10/site-packages/django/shortcuts.py", line 19, in render
    content = loader.render_to_string(template_name, context, request, using=using)
  File "/home/nurmuhammad/.local/lib/python3.10/site-packages/django/template/loader.py", line 62, in render_to_string
    return template.render(context, request)
  File "/home/nurmuhammad/.local/lib/python3.10/site-packages/django/template/backends/django.py", line 61, in render
    return self.template.render(context)
  File "/home/nurmuhammad/.local/lib/python3.10/site-packages/django/template/base.py", line 170, in render
    return self._render(context)
  File "/home/nurmuhammad/.local/lib/python3.10/site-packages/django/template/base.py", line 162, in _render
    return self.nodelist.render(context)
  File "/home/nurmuhammad/.local/lib/python3.10/site-packages/django/template/base.py", line 938, in render
    bit = node.render_annotated(context)
  File "/home/nurmuhammad/.local/lib/python3.10/site-packages/django/template/base.py", line 905, in render_annotated
    return self.render(context)
  File "/home/nurmuhammad/.local/lib/python3.10/site-packages/django/template/loader_tags.py", line 150, in render
    return compiled_parent._render(context)
  File "/home/nurmuhammad/.local/lib/python3.10/site-packages/django/template/base.py", line 162, in _render
    return self.nodelist.render(context)
  File "/home/nurmuhammad/.local/lib/python3.10/site-packages/django/template/base.py", line 938, in render
    bit = node.render_annotated(context)
  File "/home/nurmuhammad/.local/lib/python3.10/site-packages/django/template/base.py", line 905, in render_annotated
    return self.render(context)
  File "/home/nurmuhammad/.local/lib/python3.10/site-packages/django/template/loader_tags.py", line 62, in render
    result = block.nodelist.render(context)
  File "/home/nurmuhammad/.local/lib/python3.10/site-packages/django/template/base.py", line 938, in render
    bit = node.render_annotated(context)
  File "/home/nurmuhammad/.local/lib/python3.10/site-packages/django/template/base.py", line 905, in render_annotated
    return self.render(context)
  File "/home/nurmuhammad/.local/lib/python3.10/site-packages/django/template/defaulttags.py", line 449, in render
    url = reverse(view_name, args=args, kwargs=kwargs, current_app=current_app)
  File "/home/nurmuhammad/.local/lib/python3.10/site-packages/django/urls/base.py", line 82, in reverse
    raise NoReverseMatch("%s is not a registered namespace" % key)
django.urls.exceptions.NoReverseMatch: 'cart' is not a registered namespace
2023-02-11 18:37:17,922 django.request ERROR    Internal Server Error: /store/cat-1/shoes/
Traceback (most recent call last):
  File "/home/nurmuhammad/.local/lib/python3.10/site-packages/django/urls/base.py", line 71, in reverse
    extra, resolver = resolver.namespace_dict[ns]
KeyError: 'cart'

During handling of the above exception, another exception occurred:

Traceback (most recent call last):
  File "/home/nurmuhammad/.local/lib/python3.10/site-packages/django/core/handlers/exception.py", line 47, in inner
    response = get_response(request)
  File "/home/nurmuhammad/.local/lib/python3.10/site-packages/django/core/handlers/base.py", line 181, in _get_response
    response = wrapped_callback(request, *callback_args, **callback_kwargs)
  File "/home/nurmuhammad/e-commerce/backend/src/apps/store/views/product.py", line 51, in product_detail_view
    return render(request, "store/product_detail.html", context)
  File "/home/nurmuhammad/.local/lib/python3.10/site-packages/django/shortcuts.py", line 19, in render
    content = loader.render_to_string(template_name, context, request, using=using)
  File "/home/nurmuhammad/.local/lib/python3.10/site-packages/django/template/loader.py", line 62, in render_to_string
    return template.render(context, request)
  File "/home/nurmuhammad/.local/lib/python3.10/site-packages/django/template/backends/django.py", line 61, in render
    return self.template.render(context)
  File "/home/nurmuhammad/.local/lib/python3.10/site-packages/django/template/base.py", line 170, in render
    return self._render(context)
  File "/home/nurmuhammad/.local/lib/python3.10/site-packages/django/template/base.py", line 162, in _render
    return self.nodelist.render(context)
  File "/home/nurmuhammad/.local/lib/python3.10/site-packages/django/template/base.py", line 938, in render
    bit = node.render_annotated(context)
  File "/home/nurmuhammad/.local/lib/python3.10/site-packages/django/template/base.py", line 905, in render_annotated
    return self.render(context)
  File "/home/nurmuhammad/.local/lib/python3.10/site-packages/django/template/loader_tags.py", line 150, in render
    return compiled_parent._render(context)
  File "/home/nurmuhammad/.local/lib/python3.10/site-packages/django/template/base.py", line 162, in _render
    return self.nodelist.render(context)
  File "/home/nurmuhammad/.local/lib/python3.10/site-packages/django/template/base.py", line 938, in render
    bit = node.render_annotated(context)
  File "/home/nurmuhammad/.local/lib/python3.10/site-packages/django/template/base.py", line 905, in render_annotated
    return self.render(context)
  File "/home/nurmuhammad/.local/lib/python3.10/site-packages/django/template/loader_tags.py", line 62, in render
    result = block.nodelist.render(context)
  File "/home/nurmuhammad/.local/lib/python3.10/site-packages/django/template/base.py", line 938, in render
    bit = node.render_annotated(context)
  File "/home/nurmuhammad/.local/lib/python3.10/site-packages/django/template/base.py", line 905, in render_annotated
    return self.render(context)
  File "/home/nurmuhammad/.local/lib/python3.10/site-packages/django/template/defaulttags.py", line 449, in render
    url = reverse(view_name, args=args, kwargs=kwargs, current_app=current_app)
  File "/home/nurmuhammad/.local/lib/python3.10/site-packages/django/urls/base.py", line 82, in reverse
    raise NoReverseMatch("%s is not a registered namespace" % key)
django.urls.exceptions.NoReverseMatch: 'cart' is not a registered namespace
2023-02-11 18:54:27,116 django.request ERROR    Internal Server Error: /store/cat-2/trainers/
Traceback (most recent call last):
  File "/home/nurmuhammad/.local/lib/python3.10/site-packages/django/urls/base.py", line 71, in reverse
    extra, resolver = resolver.namespace_dict[ns]
KeyError: 'cart'

During handling of the above exception, another exception occurred:

Traceback (most recent call last):
  File "/home/nurmuhammad/.local/lib/python3.10/site-packages/django/core/handlers/exception.py", line 47, in inner
    response = get_response(request)
  File "/home/nurmuhammad/.local/lib/python3.10/site-packages/django/core/handlers/base.py", line 181, in _get_response
    response = wrapped_callback(request, *callback_args, **callback_kwargs)
  File "/home/nurmuhammad/e-commerce/backend/src/apps/store/views/product.py", line 51, in product_detail_view
    return render(request, "store/product_detail.html", context)
  File "/home/nurmuhammad/.local/lib/python3.10/site-packages/django/shortcuts.py", line 19, in render
    content = loader.render_to_string(template_name, context, request, using=using)
  File "/home/nurmuhammad/.local/lib/python3.10/site-packages/django/template/loader.py", line 62, in render_to_string
    return template.render(context, request)
  File "/home/nurmuhammad/.local/lib/python3.10/site-packages/django/template/backends/django.py", line 61, in render
    return self.template.render(context)
  File "/home/nurmuhammad/.local/lib/python3.10/site-packages/django/template/base.py", line 170, in render
    return self._render(context)
  File "/home/nurmuhammad/.local/lib/python3.10/site-packages/django/template/base.py", line 162, in _render
    return self.nodelist.render(context)
  File "/home/nurmuhammad/.local/lib/python3.10/site-packages/django/template/base.py", line 938, in render
    bit = node.render_annotated(context)
  File "/home/nurmuhammad/.local/lib/python3.10/site-packages/django/template/base.py", line 905, in render_annotated
    return self.render(context)
  File "/home/nurmuhammad/.local/lib/python3.10/site-packages/django/template/loader_tags.py", line 150, in render
    return compiled_parent._render(context)
  File "/home/nurmuhammad/.local/lib/python3.10/site-packages/django/template/base.py", line 162, in _render
    return self.nodelist.render(context)
  File "/home/nurmuhammad/.local/lib/python3.10/site-packages/django/template/base.py", line 938, in render
    bit = node.render_annotated(context)
  File "/home/nurmuhammad/.local/lib/python3.10/site-packages/django/template/base.py", line 905, in render_annotated
    return self.render(context)
  File "/home/nurmuhammad/.local/lib/python3.10/site-packages/django/template/loader_tags.py", line 62, in render
    result = block.nodelist.render(context)
  File "/home/nurmuhammad/.local/lib/python3.10/site-packages/django/template/base.py", line 938, in render
    bit = node.render_annotated(context)
  File "/home/nurmuhammad/.local/lib/python3.10/site-packages/django/template/base.py", line 905, in render_annotated
    return self.render(context)
  File "/home/nurmuhammad/.local/lib/python3.10/site-packages/django/template/defaulttags.py", line 449, in render
    url = reverse(view_name, args=args, kwargs=kwargs, current_app=current_app)
  File "/home/nurmuhammad/.local/lib/python3.10/site-packages/django/urls/base.py", line 82, in reverse
    raise NoReverseMatch("%s is not a registered namespace" % key)
django.urls.exceptions.NoReverseMatch: 'cart' is not a registered namespace
2023-02-11 19:03:32,246 django.request ERROR    Internal Server Error: /cart/add/cart/
Traceback (most recent call last):
  File "/home/nurmuhammad/.local/lib/python3.10/site-packages/django/db/backends/utils.py", line 84, in _execute
    return self.cursor.execute(sql, params)
  File "/home/nurmuhammad/.local/lib/python3.10/site-packages/django/db/backends/sqlite3/base.py", line 423, in execute
    return Database.Cursor.execute(self, query, params)
sqlite3.OperationalError: no such table: cart_cart

The above exception was the direct cause of the following exception:

Traceback (most recent call last):
  File "/home/nurmuhammad/.local/lib/python3.10/site-packages/django/core/handlers/exception.py", line 47, in inner
    response = get_response(request)
  File "/home/nurmuhammad/.local/lib/python3.10/site-packages/django/core/handlers/base.py", line 181, in _get_response
    response = wrapped_callback(request, *callback_args, **callback_kwargs)
  File "/home/nurmuhammad/e-commerce/backend/src/apps/cart/views.py", line 24, in add_cart
    cart, created = Cart.objects.get_or_create(user=request.user)
  File "/home/nurmuhammad/.local/lib/python3.10/site-packages/django/db/models/manager.py", line 85, in manager_method
    return getattr(self.get_queryset(), name)(*args, **kwargs)
  File "/home/nurmuhammad/.local/lib/python3.10/site-packages/django/db/models/query.py", line 581, in get_or_create
    return self.get(**kwargs), False
  File "/home/nurmuhammad/.local/lib/python3.10/site-packages/django/db/models/query.py", line 431, in get
    num = len(clone)
  File "/home/nurmuhammad/.local/lib/python3.10/site-packages/django/db/models/query.py", line 262, in __len__
    self._fetch_all()
  File "/home/nurmuhammad/.local/lib/python3.10/site-packages/django/db/models/query.py", line 1324, in _fetch_all
    self._result_cache = list(self._iterable_class(self))
  File "/home/nurmuhammad/.local/lib/python3.10/site-packages/django/db/models/query.py", line 51, in __iter__
    results = compiler.execute_sql(chunked_fetch=self.chunked_fetch, chunk_size=self.chunk_size)
  File "/home/nurmuhammad/.local/lib/python3.10/site-packages/django/db/models/sql/compiler.py", line 1175, in execute_sql
    cursor.execute(sql, params)
  File "/home/nurmuhammad/.local/lib/python3.10/site-packages/django/db/backends/utils.py", line 98, in execute
    return super().execute(sql, params)
  File "/home/nurmuhammad/.local/lib/python3.10/site-packages/django/db/backends/utils.py", line 66, in execute
    return self._execute_with_wrappers(sql, params, many=False, executor=self._execute)
  File "/home/nurmuhammad/.local/lib/python3.10/site-packages/django/db/backends/utils.py", line 75, in _execute_with_wrappers
    return executor(sql, params, many, context)
  File "/home/nurmuhammad/.local/lib/python3.10/site-packages/django/db/backends/utils.py", line 79, in _execute
    with self.db.wrap_database_errors:
  File "/home/nurmuhammad/.local/lib/python3.10/site-packages/django/db/utils.py", line 90, in __exit__
    raise dj_exc_value.with_traceback(traceback) from exc_value
  File "/home/nurmuhammad/.local/lib/python3.10/site-packages/django/db/backends/utils.py", line 84, in _execute
    return self.cursor.execute(sql, params)
  File "/home/nurmuhammad/.local/lib/python3.10/site-packages/django/db/backends/sqlite3/base.py", line 423, in execute
    return Database.Cursor.execute(self, query, params)
django.db.utils.OperationalError: no such table: cart_cart
2023-02-11 19:03:37,205 django.request ERROR    Internal Server Error: /cart/add/cart/
Traceback (most recent call last):
  File "/home/nurmuhammad/.local/lib/python3.10/site-packages/django/db/backends/utils.py", line 84, in _execute
    return self.cursor.execute(sql, params)
  File "/home/nurmuhammad/.local/lib/python3.10/site-packages/django/db/backends/sqlite3/base.py", line 423, in execute
    return Database.Cursor.execute(self, query, params)
sqlite3.OperationalError: no such table: cart_cart

The above exception was the direct cause of the following exception:

Traceback (most recent call last):
  File "/home/nurmuhammad/.local/lib/python3.10/site-packages/django/core/handlers/exception.py", line 47, in inner
    response = get_response(request)
  File "/home/nurmuhammad/.local/lib/python3.10/site-packages/django/core/handlers/base.py", line 181, in _get_response
    response = wrapped_callback(request, *callback_args, **callback_kwargs)
  File "/home/nurmuhammad/e-commerce/backend/src/apps/cart/views.py", line 24, in add_cart
    cart, created = Cart.objects.get_or_create(user=request.user)
  File "/home/nurmuhammad/.local/lib/python3.10/site-packages/django/db/models/manager.py", line 85, in manager_method
    return getattr(self.get_queryset(), name)(*args, **kwargs)
  File "/home/nurmuhammad/.local/lib/python3.10/site-packages/django/db/models/query.py", line 581, in get_or_create
    return self.get(**kwargs), False
  File "/home/nurmuhammad/.local/lib/python3.10/site-packages/django/db/models/query.py", line 431, in get
    num = len(clone)
  File "/home/nurmuhammad/.local/lib/python3.10/site-packages/django/db/models/query.py", line 262, in __len__
    self._fetch_all()
  File "/home/nurmuhammad/.local/lib/python3.10/site-packages/django/db/models/query.py", line 1324, in _fetch_all
    self._result_cache = list(self._iterable_class(self))
  File "/home/nurmuhammad/.local/lib/python3.10/site-packages/django/db/models/query.py", line 51, in __iter__
    results = compiler.execute_sql(chunked_fetch=self.chunked_fetch, chunk_size=self.chunk_size)
  File "/home/nurmuhammad/.local/lib/python3.10/site-packages/django/db/models/sql/compiler.py", line 1175, in execute_sql
    cursor.execute(sql, params)
  File "/home/nurmuhammad/.local/lib/python3.10/site-packages/django/db/backends/utils.py", line 98, in execute
    return super().execute(sql, params)
  File "/home/nurmuhammad/.local/lib/python3.10/site-packages/django/db/backends/utils.py", line 66, in execute
    return self._execute_with_wrappers(sql, params, many=False, executor=self._execute)
  File "/home/nurmuhammad/.local/lib/python3.10/site-packages/django/db/backends/utils.py", line 75, in _execute_with_wrappers
    return executor(sql, params, many, context)
  File "/home/nurmuhammad/.local/lib/python3.10/site-packages/django/db/backends/utils.py", line 79, in _execute
    with self.db.wrap_database_errors:
  File "/home/nurmuhammad/.local/lib/python3.10/site-packages/django/db/utils.py", line 90, in __exit__
    raise dj_exc_value.with_traceback(traceback) from exc_value
  File "/home/nurmuhammad/.local/lib/python3.10/site-packages/django/db/backends/utils.py", line 84, in _execute
    return self.cursor.execute(sql, params)
  File "/home/nurmuhammad/.local/lib/python3.10/site-packages/django/db/backends/sqlite3/base.py", line 423, in execute
    return Database.Cursor.execute(self, query, params)
django.db.utils.OperationalError: no such table: cart_cart
