2023-02-07 07:58:36,056 django.request ERROR    Internal Server Error: /login/
Traceback (most recent call last):
  File "/home/nurmuhammad/.local/lib/python3.10/site-packages/django/core/handlers/exception.py", line 47, in inner
    response = get_response(request)
  File "/home/nurmuhammad/.local/lib/python3.10/site-packages/django/core/handlers/base.py", line 181, in _get_response
    response = wrapped_callback(request, *callback_args, **callback_kwargs)
TypeError: login() missing 1 required positional argument: 'user'
2023-02-07 07:58:38,457 django.request ERROR    Internal Server Error: /login/
Traceback (most recent call last):
  File "/home/nurmuhammad/.local/lib/python3.10/site-packages/django/core/handlers/exception.py", line 47, in inner
    response = get_response(request)
  File "/home/nurmuhammad/.local/lib/python3.10/site-packages/django/core/handlers/base.py", line 181, in _get_response
    response = wrapped_callback(request, *callback_args, **callback_kwargs)
TypeError: login() missing 1 required positional argument: 'user'
2023-02-07 07:58:39,446 django.request ERROR    Internal Server Error: /login/
Traceback (most recent call last):
  File "/home/nurmuhammad/.local/lib/python3.10/site-packages/django/core/handlers/exception.py", line 47, in inner
    response = get_response(request)
  File "/home/nurmuhammad/.local/lib/python3.10/site-packages/django/core/handlers/base.py", line 181, in _get_response
    response = wrapped_callback(request, *callback_args, **callback_kwargs)
TypeError: login() missing 1 required positional argument: 'user'
2023-02-07 07:58:39,765 django.request ERROR    Internal Server Error: /login/
Traceback (most recent call last):
  File "/home/nurmuhammad/.local/lib/python3.10/site-packages/django/core/handlers/exception.py", line 47, in inner
    response = get_response(request)
  File "/home/nurmuhammad/.local/lib/python3.10/site-packages/django/core/handlers/base.py", line 181, in _get_response
    response = wrapped_callback(request, *callback_args, **callback_kwargs)
TypeError: login() missing 1 required positional argument: 'user'
2023-02-07 07:58:40,075 django.request ERROR    Internal Server Error: /login/
Traceback (most recent call last):
  File "/home/nurmuhammad/.local/lib/python3.10/site-packages/django/core/handlers/exception.py", line 47, in inner
    response = get_response(request)
  File "/home/nurmuhammad/.local/lib/python3.10/site-packages/django/core/handlers/base.py", line 181, in _get_response
    response = wrapped_callback(request, *callback_args, **callback_kwargs)
TypeError: login() missing 1 required positional argument: 'user'
2023-02-07 07:58:44,686 django.request ERROR    Internal Server Error: /login/
Traceback (most recent call last):
  File "/home/nurmuhammad/.local/lib/python3.10/site-packages/django/core/handlers/exception.py", line 47, in inner
    response = get_response(request)
  File "/home/nurmuhammad/.local/lib/python3.10/site-packages/django/core/handlers/base.py", line 181, in _get_response
    response = wrapped_callback(request, *callback_args, **callback_kwargs)
TypeError: login() missing 1 required positional argument: 'user'
2023-02-07 07:59:33,978 django.request ERROR    Internal Server Error: /login/
Traceback (most recent call last):
  File "/home/nurmuhammad/.local/lib/python3.10/site-packages/django/core/handlers/exception.py", line 47, in inner
    response = get_response(request)
  File "/home/nurmuhammad/.local/lib/python3.10/site-packages/django/core/handlers/base.py", line 181, in _get_response
    response = wrapped_callback(request, *callback_args, **callback_kwargs)
TypeError: login() missing 1 required positional argument: 'user'
2023-02-07 08:04:15,849 django.request ERROR    Internal Server Error: /login/
Traceback (most recent call last):
  File "/home/nurmuhammad/.local/lib/python3.10/site-packages/django/core/handlers/exception.py", line 47, in inner
    response = get_response(request)
  File "/home/nurmuhammad/.local/lib/python3.10/site-packages/django/core/handlers/base.py", line 181, in _get_response
    response = wrapped_callback(request, *callback_args, **callback_kwargs)
TypeError: login() missing 1 required positional argument: 'user'
2023-02-07 10:53:53,724 django.request ERROR    Internal Server Error: /login/
Traceback (most recent call last):
  File "/home/nurmuhammad/.local/lib/python3.10/site-packages/django/core/handlers/exception.py", line 47, in inner
    response = get_response(request)
  File "/home/nurmuhammad/.local/lib/python3.10/site-packages/django/core/handlers/base.py", line 181, in _get_response
    response = wrapped_callback(request, *callback_args, **callback_kwargs)
  File "/home/nurmuhammad/e-commerce/backend/src/apps/accounts/views/login.py", line 19, in _wrapped_view
    return view_func(request, *args, **kwargs)
  File "/home/nurmuhammad/e-commerce/backend/src/apps/accounts/views/login.py", line 40, in login
    login(request, user)
  File "/home/nurmuhammad/e-commerce/backend/src/apps/accounts/views/login.py", line 19, in _wrapped_view
    return view_func(request, *args, **kwargs)
TypeError: login() takes 1 positional argument but 2 were given
2023-02-07 10:54:15,265 django.request ERROR    Internal Server Error: /login/
Traceback (most recent call last):
  File "/home/nurmuhammad/.local/lib/python3.10/site-packages/django/core/handlers/exception.py", line 47, in inner
    response = get_response(request)
  File "/home/nurmuhammad/.local/lib/python3.10/site-packages/django/core/handlers/base.py", line 181, in _get_response
    response = wrapped_callback(request, *callback_args, **callback_kwargs)
  File "/home/nurmuhammad/e-commerce/backend/src/apps/accounts/views/login.py", line 19, in _wrapped_view
    return view_func(request, *args, **kwargs)
  File "/home/nurmuhammad/e-commerce/backend/src/apps/accounts/views/login.py", line 40, in login
    login(request, user)
  File "/home/nurmuhammad/e-commerce/backend/src/apps/accounts/views/login.py", line 19, in _wrapped_view
    return view_func(request, *args, **kwargs)
TypeError: login() takes 1 positional argument but 2 were given
2023-02-07 10:57:33,654 django.request ERROR    Internal Server Error: /login/
Traceback (most recent call last):
  File "/home/nurmuhammad/.local/lib/python3.10/site-packages/django/core/handlers/exception.py", line 47, in inner
    response = get_response(request)
  File "/home/nurmuhammad/.local/lib/python3.10/site-packages/django/core/handlers/base.py", line 181, in _get_response
    response = wrapped_callback(request, *callback_args, **callback_kwargs)
  File "/home/nurmuhammad/e-commerce/backend/src/apps/accounts/views/login.py", line 39, in login
    login(request, user)
TypeError: login() takes 1 positional argument but 2 were given
2023-02-07 11:06:08,114 django.request ERROR    Internal Server Error: /login/
Traceback (most recent call last):
  File "/home/nurmuhammad/.local/lib/python3.10/site-packages/django/core/handlers/exception.py", line 47, in inner
    response = get_response(request)
  File "/home/nurmuhammad/.local/lib/python3.10/site-packages/django/core/handlers/base.py", line 181, in _get_response
    response = wrapped_callback(request, *callback_args, **callback_kwargs)
  File "/home/nurmuhammad/e-commerce/backend/src/apps/accounts/views/login.py", line 39, in login
    login(request, user)
TypeError: login() takes 1 positional argument but 2 were given
2023-02-07 11:07:35,534 django.request ERROR    Internal Server Error: /login/
Traceback (most recent call last):
  File "/home/nurmuhammad/.local/lib/python3.10/site-packages/django/core/handlers/exception.py", line 47, in inner
    response = get_response(request)
  File "/home/nurmuhammad/.local/lib/python3.10/site-packages/django/core/handlers/base.py", line 181, in _get_response
    response = wrapped_callback(request, *callback_args, **callback_kwargs)
  File "/home/nurmuhammad/e-commerce/backend/src/apps/accounts/views/login.py", line 19, in _wrapped_view
    return view_func(request, *args, **kwargs)
  File "/home/nurmuhammad/e-commerce/backend/src/apps/accounts/views/login.py", line 39, in login
    login(request, user)
  File "/home/nurmuhammad/e-commerce/backend/src/apps/accounts/views/login.py", line 19, in _wrapped_view
    return view_func(request, *args, **kwargs)
TypeError: login() takes 1 positional argument but 2 were given
2023-02-07 11:09:01,004 django.request ERROR    Internal Server Error: /login/
Traceback (most recent call last):
  File "/home/nurmuhammad/.local/lib/python3.10/site-packages/django/core/handlers/exception.py", line 47, in inner
    response = get_response(request)
  File "/home/nurmuhammad/.local/lib/python3.10/site-packages/django/core/handlers/base.py", line 181, in _get_response
    response = wrapped_callback(request, *callback_args, **callback_kwargs)
  File "/home/nurmuhammad/e-commerce/backend/src/apps/accounts/views/login.py", line 19, in _wrapped_view
    return view_func(request, *args, **kwargs)
  File "/home/nurmuhammad/e-commerce/backend/src/apps/accounts/views/login.py", line 39, in login
    login(request, user)
  File "/home/nurmuhammad/e-commerce/backend/src/apps/accounts/views/login.py", line 19, in _wrapped_view
    return view_func(request, *args, **kwargs)
TypeError: login() takes 1 positional argument but 2 were given
2023-02-11 10:39:21,979 django.request ERROR    Internal Server Error: /
Traceback (most recent call last):
  File "/home/nurmuhammad/.local/lib/python3.10/site-packages/django/template/backends/django.py", line 61, in render
    return self.template.render(context)
  File "/home/nurmuhammad/.local/lib/python3.10/site-packages/django/template/base.py", line 170, in render
    return self._render(context)
  File "/home/nurmuhammad/.local/lib/python3.10/site-packages/django/template/base.py", line 162, in _render
    return self.nodelist.render(context)
  File "/home/nurmuhammad/.local/lib/python3.10/site-packages/django/template/base.py", line 938, in render
    bit = node.render_annotated(context)
  File "/home/nurmuhammad/.local/lib/python3.10/site-packages/django/template/base.py", line 905, in render_annotated
    return self.render(context)
  File "/home/nurmuhammad/.local/lib/python3.10/site-packages/django/template/loader_tags.py", line 150, in render
    return compiled_parent._render(context)
  File "/home/nurmuhammad/.local/lib/python3.10/site-packages/django/template/base.py", line 162, in _render
    return self.nodelist.render(context)
  File "/home/nurmuhammad/.local/lib/python3.10/site-packages/django/template/base.py", line 938, in render
    bit = node.render_annotated(context)
  File "/home/nurmuhammad/.local/lib/python3.10/site-packages/django/template/base.py", line 905, in render_annotated
    return self.render(context)
  File "/home/nurmuhammad/.local/lib/python3.10/site-packages/django/template/loader_tags.py", line 183, in render
    template = context.template.engine.select_template(template_name)
  File "/home/nurmuhammad/.local/lib/python3.10/site-packages/django/template/engine.py", line 180, in select_template
    raise TemplateDoesNotExist(', '.join(not_found))
django.template.exceptions.TemplateDoesNotExist: include/message.html

The above exception was the direct cause of the following exception:

Traceback (most recent call last):
  File "/home/nurmuhammad/.local/lib/python3.10/site-packages/django/core/handlers/exception.py", line 47, in inner
    response = get_response(request)
  File "/home/nurmuhammad/.local/lib/python3.10/site-packages/django/core/handlers/base.py", line 204, in _get_response
    response = response.render()
  File "/home/nurmuhammad/.local/lib/python3.10/site-packages/django/template/response.py", line 105, in render
    self.content = self.rendered_content
  File "/home/nurmuhammad/.local/lib/python3.10/site-packages/django/template/response.py", line 83, in rendered_content
    return template.render(context, self._request)
  File "/home/nurmuhammad/.local/lib/python3.10/site-packages/django/template/backends/django.py", line 63, in render
    reraise(exc, self.backend)
  File "/home/nurmuhammad/.local/lib/python3.10/site-packages/django/template/backends/django.py", line 84, in reraise
    raise new from exc
django.template.exceptions.TemplateDoesNotExist: include/message.html
2023-02-11 12:23:39,769 django.request ERROR    Internal Server Error: /
Traceback (most recent call last):
  File "/home/nurmuhammad/.local/lib/python3.10/site-packages/django/template/backends/django.py", line 61, in render
    return self.template.render(context)
  File "/home/nurmuhammad/.local/lib/python3.10/site-packages/django/template/base.py", line 170, in render
    return self._render(context)
  File "/home/nurmuhammad/.local/lib/python3.10/site-packages/django/template/base.py", line 162, in _render
    return self.nodelist.render(context)
  File "/home/nurmuhammad/.local/lib/python3.10/site-packages/django/template/base.py", line 938, in render
    bit = node.render_annotated(context)
  File "/home/nurmuhammad/.local/lib/python3.10/site-packages/django/template/base.py", line 905, in render_annotated
    return self.render(context)
  File "/home/nurmuhammad/.local/lib/python3.10/site-packages/django/template/loader_tags.py", line 150, in render
    return compiled_parent._render(context)
  File "/home/nurmuhammad/.local/lib/python3.10/site-packages/django/template/base.py", line 162, in _render
    return self.nodelist.render(context)
  File "/home/nurmuhammad/.local/lib/python3.10/site-packages/django/template/base.py", line 938, in render
    bit = node.render_annotated(context)
  File "/home/nurmuhammad/.local/lib/python3.10/site-packages/django/template/base.py", line 905, in render_annotated
    return self.render(context)
  File "/home/nurmuhammad/.local/lib/python3.10/site-packages/django/template/loader_tags.py", line 183, in render
    template = context.template.engine.select_template(template_name)
  File "/home/nurmuhammad/.local/lib/python3.10/site-packages/django/template/engine.py", line 180, in select_template
    raise TemplateDoesNotExist(', '.join(not_found))
django.template.exceptions.TemplateDoesNotExist: include/message.html

The above exception was the direct cause of the following exception:

Traceback (most recent call last):
  File "/home/nurmuhammad/.local/lib/python3.10/site-packages/django/core/handlers/exception.py", line 47, in inner
    response = get_response(request)
  File "/home/nurmuhammad/.local/lib/python3.10/site-packages/django/core/handlers/base.py", line 204, in _get_response
    response = response.render()
  File "/home/nurmuhammad/.local/lib/python3.10/site-packages/django/template/response.py", line 105, in render
    self.content = self.rendered_content
  File "/home/nurmuhammad/.local/lib/python3.10/site-packages/django/template/response.py", line 83, in rendered_content
    return template.render(context, self._request)
  File "/home/nurmuhammad/.local/lib/python3.10/site-packages/django/template/backends/django.py", line 63, in render
    reraise(exc, self.backend)
  File "/home/nurmuhammad/.local/lib/python3.10/site-packages/django/template/backends/django.py", line 84, in reraise
    raise new from exc
django.template.exceptions.TemplateDoesNotExist: include/message.html
2023-02-11 12:23:40,853 django.request ERROR    Internal Server Error: /
Traceback (most recent call last):
  File "/home/nurmuhammad/.local/lib/python3.10/site-packages/django/template/backends/django.py", line 61, in render
    return self.template.render(context)
  File "/home/nurmuhammad/.local/lib/python3.10/site-packages/django/template/base.py", line 170, in render
    return self._render(context)
  File "/home/nurmuhammad/.local/lib/python3.10/site-packages/django/template/base.py", line 162, in _render
    return self.nodelist.render(context)
  File "/home/nurmuhammad/.local/lib/python3.10/site-packages/django/template/base.py", line 938, in render
    bit = node.render_annotated(context)
  File "/home/nurmuhammad/.local/lib/python3.10/site-packages/django/template/base.py", line 905, in render_annotated
    return self.render(context)
  File "/home/nurmuhammad/.local/lib/python3.10/site-packages/django/template/loader_tags.py", line 150, in render
    return compiled_parent._render(context)
  File "/home/nurmuhammad/.local/lib/python3.10/site-packages/django/template/base.py", line 162, in _render
    return self.nodelist.render(context)
  File "/home/nurmuhammad/.local/lib/python3.10/site-packages/django/template/base.py", line 938, in render
    bit = node.render_annotated(context)
  File "/home/nurmuhammad/.local/lib/python3.10/site-packages/django/template/base.py", line 905, in render_annotated
    return self.render(context)
  File "/home/nurmuhammad/.local/lib/python3.10/site-packages/django/template/loader_tags.py", line 183, in render
    template = context.template.engine.select_template(template_name)
  File "/home/nurmuhammad/.local/lib/python3.10/site-packages/django/template/engine.py", line 180, in select_template
    raise TemplateDoesNotExist(', '.join(not_found))
django.template.exceptions.TemplateDoesNotExist: include/message.html

The above exception was the direct cause of the following exception:

Traceback (most recent call last):
  File "/home/nurmuhammad/.local/lib/python3.10/site-packages/django/core/handlers/exception.py", line 47, in inner
    response = get_response(request)
  File "/home/nurmuhammad/.local/lib/python3.10/site-packages/django/core/handlers/base.py", line 204, in _get_response
    response = response.render()
  File "/home/nurmuhammad/.local/lib/python3.10/site-packages/django/template/response.py", line 105, in render
    self.content = self.rendered_content
  File "/home/nurmuhammad/.local/lib/python3.10/site-packages/django/template/response.py", line 83, in rendered_content
    return template.render(context, self._request)
  File "/home/nurmuhammad/.local/lib/python3.10/site-packages/django/template/backends/django.py", line 63, in render
    reraise(exc, self.backend)
  File "/home/nurmuhammad/.local/lib/python3.10/site-packages/django/template/backends/django.py", line 84, in reraise
    raise new from exc
django.template.exceptions.TemplateDoesNotExist: include/message.html
2023-02-11 12:23:43,345 django.request ERROR    Internal Server Error: /
Traceback (most recent call last):
  File "/home/nurmuhammad/.local/lib/python3.10/site-packages/django/template/backends/django.py", line 61, in render
    return self.template.render(context)
  File "/home/nurmuhammad/.local/lib/python3.10/site-packages/django/template/base.py", line 170, in render
    return self._render(context)
  File "/home/nurmuhammad/.local/lib/python3.10/site-packages/django/template/base.py", line 162, in _render
    return self.nodelist.render(context)
  File "/home/nurmuhammad/.local/lib/python3.10/site-packages/django/template/base.py", line 938, in render
    bit = node.render_annotated(context)
  File "/home/nurmuhammad/.local/lib/python3.10/site-packages/django/template/base.py", line 905, in render_annotated
    return self.render(context)
  File "/home/nurmuhammad/.local/lib/python3.10/site-packages/django/template/loader_tags.py", line 150, in render
    return compiled_parent._render(context)
  File "/home/nurmuhammad/.local/lib/python3.10/site-packages/django/template/base.py", line 162, in _render
    return self.nodelist.render(context)
  File "/home/nurmuhammad/.local/lib/python3.10/site-packages/django/template/base.py", line 938, in render
    bit = node.render_annotated(context)
  File "/home/nurmuhammad/.local/lib/python3.10/site-packages/django/template/base.py", line 905, in render_annotated
    return self.render(context)
  File "/home/nurmuhammad/.local/lib/python3.10/site-packages/django/template/loader_tags.py", line 183, in render
    template = context.template.engine.select_template(template_name)
  File "/home/nurmuhammad/.local/lib/python3.10/site-packages/django/template/engine.py", line 180, in select_template
    raise TemplateDoesNotExist(', '.join(not_found))
django.template.exceptions.TemplateDoesNotExist: include/message.html

The above exception was the direct cause of the following exception:

Traceback (most recent call last):
  File "/home/nurmuhammad/.local/lib/python3.10/site-packages/django/core/handlers/exception.py", line 47, in inner
    response = get_response(request)
  File "/home/nurmuhammad/.local/lib/python3.10/site-packages/django/core/handlers/base.py", line 204, in _get_response
    response = response.render()
  File "/home/nurmuhammad/.local/lib/python3.10/site-packages/django/template/response.py", line 105, in render
    self.content = self.rendered_content
  File "/home/nurmuhammad/.local/lib/python3.10/site-packages/django/template/response.py", line 83, in rendered_content
    return template.render(context, self._request)
  File "/home/nurmuhammad/.local/lib/python3.10/site-packages/django/template/backends/django.py", line 63, in render
    reraise(exc, self.backend)
  File "/home/nurmuhammad/.local/lib/python3.10/site-packages/django/template/backends/django.py", line 84, in reraise
    raise new from exc
django.template.exceptions.TemplateDoesNotExist: include/message.html
2023-02-11 12:44:42,453 django.request ERROR    Internal Server Error: /store/cat-2/trainers/
Traceback (most recent call last):
  File "/home/nurmuhammad/.local/lib/python3.10/site-packages/django/core/handlers/exception.py", line 47, in inner
    response = get_response(request)
  File "/home/nurmuhammad/.local/lib/python3.10/site-packages/django/core/handlers/base.py", line 181, in _get_response
    response = wrapped_callback(request, *callback_args, **callback_kwargs)
  File "/home/nurmuhammad/e-commerce/backend/src/apps/store/views/product.py", line 45, in product_detail_view
    variants = ProductVariants.objects_2.colors()
AttributeError: type object 'ProductVariants' has no attribute 'objects_2'
2023-02-11 12:44:44,843 django.request ERROR    Internal Server Error: /store/cat-2/trainers/
Traceback (most recent call last):
  File "/home/nurmuhammad/.local/lib/python3.10/site-packages/django/core/handlers/exception.py", line 47, in inner
    response = get_response(request)
  File "/home/nurmuhammad/.local/lib/python3.10/site-packages/django/core/handlers/base.py", line 181, in _get_response
    response = wrapped_callback(request, *callback_args, **callback_kwargs)
  File "/home/nurmuhammad/e-commerce/backend/src/apps/store/views/product.py", line 45, in product_detail_view
    variants = ProductVariants.objects_2.colors()
AttributeError: type object 'ProductVariants' has no attribute 'objects_2'
2023-02-11 12:44:45,740 django.request ERROR    Internal Server Error: /store/cat-2/trainers/
Traceback (most recent call last):
  File "/home/nurmuhammad/.local/lib/python3.10/site-packages/django/core/handlers/exception.py", line 47, in inner
    response = get_response(request)
  File "/home/nurmuhammad/.local/lib/python3.10/site-packages/django/core/handlers/base.py", line 181, in _get_response
    response = wrapped_callback(request, *callback_args, **callback_kwargs)
  File "/home/nurmuhammad/e-commerce/backend/src/apps/store/views/product.py", line 45, in product_detail_view
    variants = ProductVariants.objects_2.colors()
AttributeError: type object 'ProductVariants' has no attribute 'objects_2'
2023-02-11 12:44:46,100 django.request ERROR    Internal Server Error: /store/cat-2/trainers/
Traceback (most recent call last):
  File "/home/nurmuhammad/.local/lib/python3.10/site-packages/django/core/handlers/exception.py", line 47, in inner
    response = get_response(request)
  File "/home/nurmuhammad/.local/lib/python3.10/site-packages/django/core/handlers/base.py", line 181, in _get_response
    response = wrapped_callback(request, *callback_args, **callback_kwargs)
  File "/home/nurmuhammad/e-commerce/backend/src/apps/store/views/product.py", line 45, in product_detail_view
    variants = ProductVariants.objects_2.colors()
AttributeError: type object 'ProductVariants' has no attribute 'objects_2'
2023-02-11 12:45:26,764 django.request ERROR    Internal Server Error: /store/cat-2/trainers/
Traceback (most recent call last):
  File "/home/nurmuhammad/.local/lib/python3.10/site-packages/django/core/handlers/exception.py", line 47, in inner
    response = get_response(request)
  File "/home/nurmuhammad/.local/lib/python3.10/site-packages/django/core/handlers/base.py", line 181, in _get_response
    response = wrapped_callback(request, *callback_args, **callback_kwargs)
  File "/home/nurmuhammad/e-commerce/backend/src/apps/store/views/product.py", line 45, in product_detail_view
    variants = ProductVariants.object_2.colors()
AttributeError: 'ProductVariantsManager' object has no attribute 'colors'
2023-02-11 12:45:28,781 django.request ERROR    Internal Server Error: /store/cat-2/trainers/
Traceback (most recent call last):
  File "/home/nurmuhammad/.local/lib/python3.10/site-packages/django/core/handlers/exception.py", line 47, in inner
    response = get_response(request)
  File "/home/nurmuhammad/.local/lib/python3.10/site-packages/django/core/handlers/base.py", line 181, in _get_response
    response = wrapped_callback(request, *callback_args, **callback_kwargs)
  File "/home/nurmuhammad/e-commerce/backend/src/apps/store/views/product.py", line 45, in product_detail_view
    variants = ProductVariants.object_2.colors()
AttributeError: 'ProductVariantsManager' object has no attribute 'colors'
2023-02-11 12:45:29,151 django.request ERROR    Internal Server Error: /store/cat-2/trainers/
Traceback (most recent call last):
  File "/home/nurmuhammad/.local/lib/python3.10/site-packages/django/core/handlers/exception.py", line 47, in inner
    response = get_response(request)
  File "/home/nurmuhammad/.local/lib/python3.10/site-packages/django/core/handlers/base.py", line 181, in _get_response
    response = wrapped_callback(request, *callback_args, **callback_kwargs)
  File "/home/nurmuhammad/e-commerce/backend/src/apps/store/views/product.py", line 45, in product_detail_view
    variants = ProductVariants.object_2.colors()
AttributeError: 'ProductVariantsManager' object has no attribute 'colors'
2023-02-11 12:45:29,658 django.request ERROR    Internal Server Error: /store/cat-2/trainers/
Traceback (most recent call last):
  File "/home/nurmuhammad/.local/lib/python3.10/site-packages/django/core/handlers/exception.py", line 47, in inner
    response = get_response(request)
  File "/home/nurmuhammad/.local/lib/python3.10/site-packages/django/core/handlers/base.py", line 181, in _get_response
    response = wrapped_callback(request, *callback_args, **callback_kwargs)
  File "/home/nurmuhammad/e-commerce/backend/src/apps/store/views/product.py", line 45, in product_detail_view
    variants = ProductVariants.object_2.colors()
AttributeError: 'ProductVariantsManager' object has no attribute 'colors'
2023-02-11 12:45:38,658 django.request ERROR    Internal Server Error: /store/cat-2/trainers/
Traceback (most recent call last):
  File "/home/nurmuhammad/.local/lib/python3.10/site-packages/django/core/handlers/exception.py", line 47, in inner
    response = get_response(request)
  File "/home/nurmuhammad/.local/lib/python3.10/site-packages/django/core/handlers/base.py", line 181, in _get_response
    response = wrapped_callback(request, *callback_args, **callback_kwargs)
  File "/home/nurmuhammad/e-commerce/backend/src/apps/store/views/product.py", line 45, in product_detail_view
    variants = ProductVariants.object_2.colors()
AttributeError: 'ProductVariantsManager' object has no attribute 'colors'
2023-02-11 12:45:41,153 django.request ERROR    Internal Server Error: /store/cat-2/trainers/
Traceback (most recent call last):
  File "/home/nurmuhammad/.local/lib/python3.10/site-packages/django/core/handlers/exception.py", line 47, in inner
    response = get_response(request)
  File "/home/nurmuhammad/.local/lib/python3.10/site-packages/django/core/handlers/base.py", line 181, in _get_response
    response = wrapped_callback(request, *callback_args, **callback_kwargs)
  File "/home/nurmuhammad/e-commerce/backend/src/apps/store/views/product.py", line 45, in product_detail_view
    variants = ProductVariants.object_2.colors()
AttributeError: 'ProductVariantsManager' object has no attribute 'colors'
2023-02-11 18:22:57,303 django.request ERROR    Internal Server Error: /store/cat-2/trainers/
Traceback (most recent call last):
  File "/home/nurmuhammad/.local/lib/python3.10/site-packages/django/core/handlers/exception.py", line 47, in inner
    response = get_response(request)
  File "/home/nurmuhammad/.local/lib/python3.10/site-packages/django/core/handlers/base.py", line 181, in _get_response
    response = wrapped_callback(request, *callback_args, **callback_kwargs)
  File "/home/nurmuhammad/e-commerce/backend/src/apps/store/views/product.py", line 45, in product_detail_view
    variants = ProductVariants.object_2.colors()
AttributeError: type object 'ProductVariants' has no attribute 'object_2'
2023-02-11 18:23:00,115 django.request ERROR    Internal Server Error: /store/cat-2/trainers/
Traceback (most recent call last):
  File "/home/nurmuhammad/.local/lib/python3.10/site-packages/django/core/handlers/exception.py", line 47, in inner
    response = get_response(request)
  File "/home/nurmuhammad/.local/lib/python3.10/site-packages/django/core/handlers/base.py", line 181, in _get_response
    response = wrapped_callback(request, *callback_args, **callback_kwargs)
  File "/home/nurmuhammad/e-commerce/backend/src/apps/store/views/product.py", line 45, in product_detail_view
    variants = ProductVariants.object_2.colors()
AttributeError: type object 'ProductVariants' has no attribute 'object_2'
2023-02-11 18:23:01,146 django.request ERROR    Internal Server Error: /store/cat-2/trainers/
Traceback (most recent call last):
  File "/home/nurmuhammad/.local/lib/python3.10/site-packages/django/core/handlers/exception.py", line 47, in inner
    response = get_response(request)
  File "/home/nurmuhammad/.local/lib/python3.10/site-packages/django/core/handlers/base.py", line 181, in _get_response
    response = wrapped_callback(request, *callback_args, **callback_kwargs)
  File "/home/nurmuhammad/e-commerce/backend/src/apps/store/views/product.py", line 45, in product_detail_view
    variants = ProductVariants.object_2.colors()
AttributeError: type object 'ProductVariants' has no attribute 'object_2'
2023-02-11 18:23:01,443 django.request ERROR    Internal Server Error: /store/cat-2/trainers/
Traceback (most recent call last):
  File "/home/nurmuhammad/.local/lib/python3.10/site-packages/django/core/handlers/exception.py", line 47, in inner
    response = get_response(request)
  File "/home/nurmuhammad/.local/lib/python3.10/site-packages/django/core/handlers/base.py", line 181, in _get_response
    response = wrapped_callback(request, *callback_args, **callback_kwargs)
  File "/home/nurmuhammad/e-commerce/backend/src/apps/store/views/product.py", line 45, in product_detail_view
    variants = ProductVariants.object_2.colors()
AttributeError: type object 'ProductVariants' has no attribute 'object_2'
2023-02-11 18:23:01,625 django.request ERROR    Internal Server Error: /store/cat-2/trainers/
Traceback (most recent call last):
  File "/home/nurmuhammad/.local/lib/python3.10/site-packages/django/core/handlers/exception.py", line 47, in inner
    response = get_response(request)
  File "/home/nurmuhammad/.local/lib/python3.10/site-packages/django/core/handlers/base.py", line 181, in _get_response
    response = wrapped_callback(request, *callback_args, **callback_kwargs)
  File "/home/nurmuhammad/e-commerce/backend/src/apps/store/views/product.py", line 45, in product_detail_view
    variants = ProductVariants.object_2.colors()
AttributeError: type object 'ProductVariants' has no attribute 'object_2'
2023-02-11 18:23:01,937 django.request ERROR    Internal Server Error: /store/cat-2/trainers/
Traceback (most recent call last):
  File "/home/nurmuhammad/.local/lib/python3.10/site-packages/django/core/handlers/exception.py", line 47, in inner
    response = get_response(request)
  File "/home/nurmuhammad/.local/lib/python3.10/site-packages/django/core/handlers/base.py", line 181, in _get_response
    response = wrapped_callback(request, *callback_args, **callback_kwargs)
  File "/home/nurmuhammad/e-commerce/backend/src/apps/store/views/product.py", line 45, in product_detail_view
    variants = ProductVariants.object_2.colors()
AttributeError: type object 'ProductVariants' has no attribute 'object_2'
2023-02-11 18:23:02,260 django.request ERROR    Internal Server Error: /store/cat-2/trainers/
Traceback (most recent call last):
  File "/home/nurmuhammad/.local/lib/python3.10/site-packages/django/core/handlers/exception.py", line 47, in inner
    response = get_response(request)
  File "/home/nurmuhammad/.local/lib/python3.10/site-packages/django/core/handlers/base.py", line 181, in _get_response
    response = wrapped_callback(request, *callback_args, **callback_kwargs)
  File "/home/nurmuhammad/e-commerce/backend/src/apps/store/views/product.py", line 45, in product_detail_view
    variants = ProductVariants.object_2.colors()
AttributeError: type object 'ProductVariants' has no attribute 'object_2'
2023-02-11 18:23:02,584 django.request ERROR    Internal Server Error: /store/cat-2/trainers/
Traceback (most recent call last):
  File "/home/nurmuhammad/.local/lib/python3.10/site-packages/django/core/handlers/exception.py", line 47, in inner
    response = get_response(request)
  File "/home/nurmuhammad/.local/lib/python3.10/site-packages/django/core/handlers/base.py", line 181, in _get_response
    response = wrapped_callback(request, *callback_args, **callback_kwargs)
  File "/home/nurmuhammad/e-commerce/backend/src/apps/store/views/product.py", line 45, in product_detail_view
    variants = ProductVariants.object_2.colors()
AttributeError: type object 'ProductVariants' has no attribute 'object_2'
2023-02-11 18:23:02,909 django.request ERROR    Internal Server Error: /store/cat-2/trainers/
Traceback (most recent call last):
  File "/home/nurmuhammad/.local/lib/python3.10/site-packages/django/core/handlers/exception.py", line 47, in inner
    response = get_response(request)
  File "/home/nurmuhammad/.local/lib/python3.10/site-packages/django/core/handlers/base.py", line 181, in _get_response
    response = wrapped_callback(request, *callback_args, **callback_kwargs)
  File "/home/nurmuhammad/e-commerce/backend/src/apps/store/views/product.py", line 45, in product_detail_view
    variants = ProductVariants.object_2.colors()
AttributeError: type object 'ProductVariants' has no attribute 'object_2'
2023-02-11 18:23:03,227 django.request ERROR    Internal Server Error: /store/cat-2/trainers/
Traceback (most recent call last):
  File "/home/nurmuhammad/.local/lib/python3.10/site-packages/django/core/handlers/exception.py", line 47, in inner
    response = get_response(request)
  File "/home/nurmuhammad/.local/lib/python3.10/site-packages/django/core/handlers/base.py", line 181, in _get_response
    response = wrapped_callback(request, *callback_args, **callback_kwargs)
  File "/home/nurmuhammad/e-commerce/backend/src/apps/store/views/product.py", line 45, in product_detail_view
    variants = ProductVariants.object_2.colors()
AttributeError: type object 'ProductVariants' has no attribute 'object_2'
2023-02-11 18:23:03,517 django.request ERROR    Internal Server Error: /store/cat-2/trainers/
Traceback (most recent call last):
  File "/home/nurmuhammad/.local/lib/python3.10/site-packages/django/core/handlers/exception.py", line 47, in inner
    response = get_response(request)
  File "/home/nurmuhammad/.local/lib/python3.10/site-packages/django/core/handlers/base.py", line 181, in _get_response
    response = wrapped_callback(request, *callback_args, **callback_kwargs)
  File "/home/nurmuhammad/e-commerce/backend/src/apps/store/views/product.py", line 45, in product_detail_view
    variants = ProductVariants.object_2.colors()
AttributeError: type object 'ProductVariants' has no attribute 'object_2'
2023-02-11 18:23:03,812 django.request ERROR    Internal Server Error: /store/cat-2/trainers/
Traceback (most recent call last):
  File "/home/nurmuhammad/.local/lib/python3.10/site-packages/django/core/handlers/exception.py", line 47, in inner
    response = get_response(request)
  File "/home/nurmuhammad/.local/lib/python3.10/site-packages/django/core/handlers/base.py", line 181, in _get_response
    response = wrapped_callback(request, *callback_args, **callback_kwargs)
  File "/home/nurmuhammad/e-commerce/backend/src/apps/store/views/product.py", line 45, in product_detail_view
    variants = ProductVariants.object_2.colors()
AttributeError: type object 'ProductVariants' has no attribute 'object_2'
2023-02-11 18:25:35,747 django.request ERROR    Internal Server Error: /store/cat-2/trainers/
Traceback (most recent call last):
  File "/home/nurmuhammad/.local/lib/python3.10/site-packages/django/urls/base.py", line 71, in reverse
    extra, resolver = resolver.namespace_dict[ns]
KeyError: 'cart'

During handling of the above exception, another exception occurred:

Traceback (most recent call last):
  File "/home/nurmuhammad/.local/lib/python3.10/site-packages/django/core/handlers/exception.py", line 47, in inner
    response = get_response(request)
  File "/home/nurmuhammad/.local/lib/python3.10/site-packages/django/core/handlers/base.py", line 181, in _get_response
    response = wrapped_callback(request, *callback_args, **callback_kwargs)
  File "/home/nurmuhammad/e-commerce/backend/src/apps/store/views/product.py", line 51, in product_detail_view
    return render(request, "store/product_detail.html", context)
  File "/home/nurmuhammad/.local/lib/python3.10/site-packages/django/shortcuts.py", line 19, in render
    content = loader.render_to_string(template_name, context, request, using=using)
  File "/home/nurmuhammad/.local/lib/python3.10/site-packages/django/template/loader.py", line 62, in render_to_string
    return template.render(context, request)
  File "/home/nurmuhammad/.local/lib/python3.10/site-packages/django/template/backends/django.py", line 61, in render
    return self.template.render(context)
  File "/home/nurmuhammad/.local/lib/python3.10/site-packages/django/template/base.py", line 170, in render
    return self._render(context)
  File "/home/nurmuhammad/.local/lib/python3.10/site-packages/django/template/base.py", line 162, in _render
    return self.nodelist.render(context)
  File "/home/nurmuhammad/.local/lib/python3.10/site-packages/django/template/base.py", line 938, in render
    bit = node.render_annotated(context)
  File "/home/nurmuhammad/.local/lib/python3.10/site-packages/django/template/base.py", line 905, in render_annotated
    return self.render(context)
  File "/home/nurmuhammad/.local/lib/python3.10/site-packages/django/template/loader_tags.py", line 150, in render
    return compiled_parent._render(context)
  File "/home/nurmuhammad/.local/lib/python3.10/site-packages/django/template/base.py", line 162, in _render
    return self.nodelist.render(context)
  File "/home/nurmuhammad/.local/lib/python3.10/site-packages/django/template/base.py", line 938, in render
    bit = node.render_annotated(context)
  File "/home/nurmuhammad/.local/lib/python3.10/site-packages/django/template/base.py", line 905, in render_annotated
    return self.render(context)
  File "/home/nurmuhammad/.local/lib/python3.10/site-packages/django/template/loader_tags.py", line 62, in render
    result = block.nodelist.render(context)
  File "/home/nurmuhammad/.local/lib/python3.10/site-packages/django/template/base.py", line 938, in render
    bit = node.render_annotated(context)
  File "/home/nurmuhammad/.local/lib/python3.10/site-packages/django/template/base.py", line 905, in render_annotated
    return self.render(context)
  File "/home/nurmuhammad/.local/lib/python3.10/site-packages/django/template/defaulttags.py", line 449, in render
    url = reverse(view_name, args=args, kwargs=kwargs, current_app=current_app)
  File "/home/nurmuhammad/.local/lib/python3.10/site-packages/django/urls/base.py", line 82, in reverse
    raise NoReverseMatch("%s is not a registered namespace" % key)
django.urls.exceptions.NoReverseMatch: 'cart' is not a registered namespace
2023-02-11 18:25:38,061 django.request ERROR    Internal Server Error: /store/cat-2/trainers/
Traceback (most recent call last):
  File "/home/nurmuhammad/.local/lib/python3.10/site-packages/django/urls/base.py", line 71, in reverse
    extra, resolver = resolver.namespace_dict[ns]
KeyError: 'cart'

During handling of the above exception, another exception occurred:

Traceback (most recent call last):
  File "/home/nurmuhammad/.local/lib/python3.10/site-packages/django/core/handlers/exception.py", line 47, in inner
    response = get_response(request)
  File "/home/nurmuhammad/.local/lib/python3.10/site-packages/django/core/handlers/base.py", line 181, in _get_response
    response = wrapped_callback(request, *callback_args, **callback_kwargs)
  File "/home/nurmuhammad/e-commerce/backend/src/apps/store/views/product.py", line 51, in product_detail_view
    return render(request, "store/product_detail.html", context)
  File "/home/nurmuhammad/.local/lib/python3.10/site-packages/django/shortcuts.py", line 19, in render
    content = loader.render_to_string(template_name, context, request, using=using)
  File "/home/nurmuhammad/.local/lib/python3.10/site-packages/django/template/loader.py", line 62, in render_to_string
    return template.render(context, request)
  File "/home/nurmuhammad/.local/lib/python3.10/site-packages/django/template/backends/django.py", line 61, in render
    return self.template.render(context)
  File "/home/nurmuhammad/.local/lib/python3.10/site-packages/django/template/base.py", line 170, in render
    return self._render(context)
  File "/home/nurmuhammad/.local/lib/python3.10/site-packages/django/template/base.py", line 162, in _render
    return self.nodelist.render(context)
  File "/home/nurmuhammad/.local/lib/python3.10/site-packages/django/template/base.py", line 938, in render
    bit = node.render_annotated(context)
  File "/home/nurmuhammad/.local/lib/python3.10/site-packages/django/template/base.py", line 905, in render_annotated
    return self.render(context)
  File "/home/nurmuhammad/.local/lib/python3.10/site-packages/django/template/loader_tags.py", line 150, in render
    return compiled_parent._render(context)
  File "/home/nurmuhammad/.local/lib/python3.10/site-packages/django/template/base.py", line 162, in _render
    return self.nodelist.render(context)
  File "/home/nurmuhammad/.local/lib/python3.10/site-packages/django/template/base.py", line 938, in render
    bit = node.render_annotated(context)
  File "/home/nurmuhammad/.local/lib/python3.10/site-packages/django/template/base.py", line 905, in render_annotated
    return self.render(context)
  File "/home/nurmuhammad/.local/lib/python3.10/site-packages/django/template/loader_tags.py", line 62, in render
    result = block.nodelist.render(context)
  File "/home/nurmuhammad/.local/lib/python3.10/site-packages/django/template/base.py", line 938, in render
    bit = node.render_annotated(context)
  File "/home/nurmuhammad/.local/lib/python3.10/site-packages/django/template/base.py", line 905, in render_annotated
    return self.render(context)
  File "/home/nurmuhammad/.local/lib/python3.10/site-packages/django/template/defaulttags.py", line 449, in render
    url = reverse(view_name, args=args, kwargs=kwargs, current_app=current_app)
  File "/home/nurmuhammad/.local/lib/python3.10/site-packages/django/urls/base.py", line 82, in reverse
    raise NoReverseMatch("%s is not a registered namespace" % key)
django.urls.exceptions.NoReverseMatch: 'cart' is not a registered namespace
2023-02-11 18:27:27,170 django.request ERROR    Internal Server Error: /store/cat-2/trainers/
Traceback (most recent call last):
  File "/home/nurmuhammad/.local/lib/python3.10/site-packages/django/urls/base.py", line 71, in reverse
    extra, resolver = resolver.namespace_dict[ns]
KeyError: 'cart'

During handling of the above exception, another exception occurred:

Traceback (most recent call last):
  File "/home/nurmuhammad/.local/lib/python3.10/site-packages/django/core/handlers/exception.py", line 47, in inner
    response = get_response(request)
  File "/home/nurmuhammad/.local/lib/python3.10/site-packages/django/core/handlers/base.py", line 181, in _get_response
    response = wrapped_callback(request, *callback_args, **callback_kwargs)
  File "/home/nurmuhammad/e-commerce/backend/src/apps/store/views/product.py", line 51, in product_detail_view
    return render(request, "store/product_detail.html", context)
  File "/home/nurmuhammad/.local/lib/python3.10/site-packages/django/shortcuts.py", line 19, in render
    content = loader.render_to_string(template_name, context, request, using=using)
  File "/home/nurmuhammad/.local/lib/python3.10/site-packages/django/template/loader.py", line 62, in render_to_string
    return template.render(context, request)
  File "/home/nurmuhammad/.local/lib/python3.10/site-packages/django/template/backends/django.py", line 61, in render
    return self.template.render(context)
  File "/home/nurmuhammad/.local/lib/python3.10/site-packages/django/template/base.py", line 170, in render
    return self._render(context)
  File "/home/nurmuhammad/.local/lib/python3.10/site-packages/django/template/base.py", line 162, in _render
    return self.nodelist.render(context)
  File "/home/nurmuhammad/.local/lib/python3.10/site-packages/django/template/base.py", line 938, in render
    bit = node.render_annotated(context)
  File "/home/nurmuhammad/.local/lib/python3.10/site-packages/django/template/base.py", line 905, in render_annotated
    return self.render(context)
  File "/home/nurmuhammad/.local/lib/python3.10/site-packages/django/template/loader_tags.py", line 150, in render
    return compiled_parent._render(context)
  File "/home/nurmuhammad/.local/lib/python3.10/site-packages/django/template/base.py", line 162, in _render
    return self.nodelist.render(context)
  File "/home/nurmuhammad/.local/lib/python3.10/site-packages/django/template/base.py", line 938, in render
    bit = node.render_annotated(context)
  File "/home/nurmuhammad/.local/lib/python3.10/site-packages/django/template/base.py", line 905, in render_annotated
    return self.render(context)
  File "/home/nurmuhammad/.local/lib/python3.10/site-packages/django/template/loader_tags.py", line 62, in render
    result = block.nodelist.render(context)
  File "/home/nurmuhammad/.local/lib/python3.10/site-packages/django/template/base.py", line 938, in render
    bit = node.render_annotated(context)
  File "/home/nurmuhammad/.local/lib/python3.10/site-packages/django/template/base.py", line 905, in render_annotated
    return self.render(context)
  File "/home/nurmuhammad/.local/lib/python3.10/site-packages/django/template/defaulttags.py", line 449, in render
    url = reverse(view_name, args=args, kwargs=kwargs, current_app=current_app)
  File "/home/nurmuhammad/.local/lib/python3.10/site-packages/django/urls/base.py", line 82, in reverse
    raise NoReverseMatch("%s is not a registered namespace" % key)
django.urls.exceptions.NoReverseMatch: 'cart' is not a registered namespace
2023-02-11 18:28:50,521 django.request ERROR    Internal Server Error: /store/cat-2/trainers/
Traceback (most recent call last):
  File "/home/nurmuhammad/.local/lib/python3.10/site-packages/django/urls/base.py", line 71, in reverse
    extra, resolver = resolver.namespace_dict[ns]
KeyError: 'cart'

During handling of the above exception, another exception occurred:

Traceback (most recent call last):
  File "/home/nurmuhammad/.local/lib/python3.10/site-packages/django/core/handlers/exception.py", line 47, in inner
    response = get_response(request)
  File "/home/nurmuhammad/.local/lib/python3.10/site-packages/django/core/handlers/base.py", line 181, in _get_response
    response = wrapped_callback(request, *callback_args, **callback_kwargs)
  File "/home/nurmuhammad/e-commerce/backend/src/apps/store/views/product.py", line 51, in product_detail_view
    return render(request, "store/product_detail.html", context)
  File "/home/nurmuhammad/.local/lib/python3.10/site-packages/django/shortcuts.py", line 19, in render
    content = loader.render_to_string(template_name, context, request, using=using)
  File "/home/nurmuhammad/.local/lib/python3.10/site-packages/django/template/loader.py", line 62, in render_to_string
    return template.render(context, request)
  File "/home/nurmuhammad/.local/lib/python3.10/site-packages/django/template/backends/django.py", line 61, in render
    return self.template.render(context)
  File "/home/nurmuhammad/.local/lib/python3.10/site-packages/django/template/base.py", line 170, in render
    return self._render(context)
  File "/home/nurmuhammad/.local/lib/python3.10/site-packages/django/template/base.py", line 162, in _render
    return self.nodelist.render(context)
  File "/home/nurmuhammad/.local/lib/python3.10/site-packages/django/template/base.py", line 938, in render
    bit = node.render_annotated(context)
  File "/home/nurmuhammad/.local/lib/python3.10/site-packages/django/template/base.py", line 905, in render_annotated
    return self.render(context)
  File "/home/nurmuhammad/.local/lib/python3.10/site-packages/django/template/loader_tags.py", line 150, in render
    return compiled_parent._render(context)
  File "/home/nurmuhammad/.local/lib/python3.10/site-packages/django/template/base.py", line 162, in _render
    return self.nodelist.render(context)
  File "/home/nurmuhammad/.local/lib/python3.10/site-packages/django/template/base.py", line 938, in render
    bit = node.render_annotated(context)
  File "/home/nurmuhammad/.local/lib/python3.10/site-packages/django/template/base.py", line 905, in render_annotated
    return self.render(context)
  File "/home/nurmuhammad/.local/lib/python3.10/site-packages/django/template/loader_tags.py", line 62, in render
    result = block.nodelist.render(context)
  File "/home/nurmuhammad/.local/lib/python3.10/site-packages/django/template/base.py", line 938, in render
    bit = node.render_annotated(context)
  File "/home/nurmuhammad/.local/lib/python3.10/site-packages/django/template/base.py", line 905, in render_annotated
    return self.render(context)
  File "/home/nurmuhammad/.local/lib/python3.10/site-packages/django/template/defaulttags.py", line 449, in render
    url = reverse(view_name, args=args, kwargs=kwargs, current_app=current_app)
  File "/home/nurmuhammad/.local/lib/python3.10/site-packages/django/urls/base.py", line 82, in reverse
    raise NoReverseMatch("%s is not a registered namespace" % key)
django.urls.exceptions.NoReverseMatch: 'cart' is not a registered namespace
2023-02-11 18:33:27,331 django.request ERROR    Internal Server Error: /store/cat-2/trainers/
Traceback (most recent call last):
  File "/home/nurmuhammad/.local/lib/python3.10/site-packages/django/urls/base.py", line 71, in reverse
    extra, resolver = resolver.namespace_dict[ns]
KeyError: 'cart'

During handling of the above exception, another exception occurred:

Traceback (most recent call last):
  File "/home/nurmuhammad/.local/lib/python3.10/site-packages/django/core/handlers/exception.py", line 47, in inner
    response = get_response(request)
  File "/home/nurmuhammad/.local/lib/python3.10/site-packages/django/core/handlers/base.py", line 181, in _get_response
    response = wrapped_callback(request, *callback_args, **callback_kwargs)
  File "/home/nurmuhammad/e-commerce/backend/src/apps/store/views/product.py", line 51, in product_detail_view
    return render(request, "store/product_detail.html", context)
  File "/home/nurmuhammad/.local/lib/python3.10/site-packages/django/shortcuts.py", line 19, in render
    content = loader.render_to_string(template_name, context, request, using=using)
  File "/home/nurmuhammad/.local/lib/python3.10/site-packages/django/template/loader.py", line 62, in render_to_string
    return template.render(context, request)
  File "/home/nurmuhammad/.local/lib/python3.10/site-packages/django/template/backends/django.py", line 61, in render
    return self.template.render(context)
  File "/home/nurmuhammad/.local/lib/python3.10/site-packages/django/template/base.py", line 170, in render
    return self._render(context)
  File "/home/nurmuhammad/.local/lib/python3.10/site-packages/django/template/base.py", line 162, in _render
    return self.nodelist.render(context)
  File "/home/nurmuhammad/.local/lib/python3.10/site-packages/django/template/base.py", line 938, in render
    bit = node.render_annotated(context)
  File "/home/nurmuhammad/.local/lib/python3.10/site-packages/django/template/base.py", line 905, in render_annotated
    return self.render(context)
  File "/home/nurmuhammad/.local/lib/python3.10/site-packages/django/template/loader_tags.py", line 150, in render
    return compiled_parent._render(context)
  File "/home/nurmuhammad/.local/lib/python3.10/site-packages/django/template/base.py", line 162, in _render
    return self.nodelist.render(context)
  File "/home/nurmuhammad/.local/lib/python3.10/site-packages/django/template/base.py", line 938, in render
    bit = node.render_annotated(context)
  File "/home/nurmuhammad/.local/lib/python3.10/site-packages/django/template/base.py", line 905, in render_annotated
    return self.render(context)
  File "/home/nurmuhammad/.local/lib/python3.10/site-packages/django/template/loader_tags.py", line 62, in render
    result = block.nodelist.render(context)
  File "/home/nurmuhammad/.local/lib/python3.10/site-packages/django/template/base.py", line 938, in render
    bit = node.render_annotated(context)
  File "/home/nurmuhammad/.local/lib/python3.10/site-packages/django/template/base.py", line 905, in render_annotated
    return self.render(context)
  File "/home/nurmuhammad/.local/lib/python3.10/site-packages/django/template/defaulttags.py", line 449, in render
    url = reverse(view_name, args=args, kwargs=kwargs, current_app=current_app)
  File "/home/nurmuhammad/.local/lib/python3.10/site-packages/django/urls/base.py", line 82, in reverse
    raise NoReverseMatch("%s is not a registered namespace" % key)
django.urls.exceptions.NoReverseMatch: 'cart' is not a registered namespace
2023-02-11 18:37:17,922 django.request ERROR    Internal Server Error: /store/cat-1/shoes/
Traceback (most recent call last):
  File "/home/nurmuhammad/.local/lib/python3.10/site-packages/django/urls/base.py", line 71, in reverse
    extra, resolver = resolver.namespace_dict[ns]
KeyError: 'cart'

During handling of the above exception, another exception occurred:

Traceback (most recent call last):
  File "/home/nurmuhammad/.local/lib/python3.10/site-packages/django/core/handlers/exception.py", line 47, in inner
    response = get_response(request)
  File "/home/nurmuhammad/.local/lib/python3.10/site-packages/django/core/handlers/base.py", line 181, in _get_response
    response = wrapped_callback(request, *callback_args, **callback_kwargs)
  File "/home/nurmuhammad/e-commerce/backend/src/apps/store/views/product.py", line 51, in product_detail_view
    return render(request, "store/product_detail.html", context)
  File "/home/nurmuhammad/.local/lib/python3.10/site-packages/django/shortcuts.py", line 19, in render
    content = loader.render_to_string(template_name, context, request, using=using)
  File "/home/nurmuhammad/.local/lib/python3.10/site-packages/django/template/loader.py", line 62, in render_to_string
    return template.render(context, request)
  File "/home/nurmuhammad/.local/lib/python3.10/site-packages/django/template/backends/django.py", line 61, in render
    return self.template.render(context)
  File "/home/nurmuhammad/.local/lib/python3.10/site-packages/django/template/base.py", line 170, in render
    return self._render(context)
  File "/home/nurmuhammad/.local/lib/python3.10/site-packages/django/template/base.py", line 162, in _render
    return self.nodelist.render(context)
  File "/home/nurmuhammad/.local/lib/python3.10/site-packages/django/template/base.py", line 938, in render
    bit = node.render_annotated(context)
  File "/home/nurmuhammad/.local/lib/python3.10/site-packages/django/template/base.py", line 905, in render_annotated
    return self.render(context)
  File "/home/nurmuhammad/.local/lib/python3.10/site-packages/django/template/loader_tags.py", line 150, in render
    return compiled_parent._render(context)
  File "/home/nurmuhammad/.local/lib/python3.10/site-packages/django/template/base.py", line 162, in _render
    return self.nodelist.render(context)
  File "/home/nurmuhammad/.local/lib/python3.10/site-packages/django/template/base.py", line 938, in render
    bit = node.render_annotated(context)
  File "/home/nurmuhammad/.local/lib/python3.10/site-packages/django/template/base.py", line 905, in render_annotated
    return self.render(context)
  File "/home/nurmuhammad/.local/lib/python3.10/site-packages/django/template/loader_tags.py", line 62, in render
    result = block.nodelist.render(context)
  File "/home/nurmuhammad/.local/lib/python3.10/site-packages/django/template/base.py", line 938, in render
    bit = node.render_annotated(context)
  File "/home/nurmuhammad/.local/lib/python3.10/site-packages/django/template/base.py", line 905, in render_annotated
    return self.render(context)
  File "/home/nurmuhammad/.local/lib/python3.10/site-packages/django/template/defaulttags.py", line 449, in render
    url = reverse(view_name, args=args, kwargs=kwargs, current_app=current_app)
  File "/home/nurmuhammad/.local/lib/python3.10/site-packages/django/urls/base.py", line 82, in reverse
    raise NoReverseMatch("%s is not a registered namespace" % key)
django.urls.exceptions.NoReverseMatch: 'cart' is not a registered namespace
2023-02-11 18:54:27,116 django.request ERROR    Internal Server Error: /store/cat-2/trainers/
Traceback (most recent call last):
  File "/home/nurmuhammad/.local/lib/python3.10/site-packages/django/urls/base.py", line 71, in reverse
    extra, resolver = resolver.namespace_dict[ns]
KeyError: 'cart'

During handling of the above exception, another exception occurred:

Traceback (most recent call last):
  File "/home/nurmuhammad/.local/lib/python3.10/site-packages/django/core/handlers/exception.py", line 47, in inner
    response = get_response(request)
  File "/home/nurmuhammad/.local/lib/python3.10/site-packages/django/core/handlers/base.py", line 181, in _get_response
    response = wrapped_callback(request, *callback_args, **callback_kwargs)
  File "/home/nurmuhammad/e-commerce/backend/src/apps/store/views/product.py", line 51, in product_detail_view
    return render(request, "store/product_detail.html", context)
  File "/home/nurmuhammad/.local/lib/python3.10/site-packages/django/shortcuts.py", line 19, in render
    content = loader.render_to_string(template_name, context, request, using=using)
  File "/home/nurmuhammad/.local/lib/python3.10/site-packages/django/template/loader.py", line 62, in render_to_string
    return template.render(context, request)
  File "/home/nurmuhammad/.local/lib/python3.10/site-packages/django/template/backends/django.py", line 61, in render
    return self.template.render(context)
  File "/home/nurmuhammad/.local/lib/python3.10/site-packages/django/template/base.py", line 170, in render
    return self._render(context)
  File "/home/nurmuhammad/.local/lib/python3.10/site-packages/django/template/base.py", line 162, in _render
    return self.nodelist.render(context)
  File "/home/nurmuhammad/.local/lib/python3.10/site-packages/django/template/base.py", line 938, in render
    bit = node.render_annotated(context)
  File "/home/nurmuhammad/.local/lib/python3.10/site-packages/django/template/base.py", line 905, in render_annotated
    return self.render(context)
  File "/home/nurmuhammad/.local/lib/python3.10/site-packages/django/template/loader_tags.py", line 150, in render
    return compiled_parent._render(context)
  File "/home/nurmuhammad/.local/lib/python3.10/site-packages/django/template/base.py", line 162, in _render
    return self.nodelist.render(context)
  File "/home/nurmuhammad/.local/lib/python3.10/site-packages/django/template/base.py", line 938, in render
    bit = node.render_annotated(context)
  File "/home/nurmuhammad/.local/lib/python3.10/site-packages/django/template/base.py", line 905, in render_annotated
    return self.render(context)
  File "/home/nurmuhammad/.local/lib/python3.10/site-packages/django/template/loader_tags.py", line 62, in render
    result = block.nodelist.render(context)
  File "/home/nurmuhammad/.local/lib/python3.10/site-packages/django/template/base.py", line 938, in render
    bit = node.render_annotated(context)
  File "/home/nurmuhammad/.local/lib/python3.10/site-packages/django/template/base.py", line 905, in render_annotated
    return self.render(context)
  File "/home/nurmuhammad/.local/lib/python3.10/site-packages/django/template/defaulttags.py", line 449, in render
    url = reverse(view_name, args=args, kwargs=kwargs, current_app=current_app)
  File "/home/nurmuhammad/.local/lib/python3.10/site-packages/django/urls/base.py", line 82, in reverse
    raise NoReverseMatch("%s is not a registered namespace" % key)
django.urls.exceptions.NoReverseMatch: 'cart' is not a registered namespace
2023-02-11 19:03:32,246 django.request ERROR    Internal Server Error: /cart/add/cart/
Traceback (most recent call last):
  File "/home/nurmuhammad/.local/lib/python3.10/site-packages/django/db/backends/utils.py", line 84, in _execute
    return self.cursor.execute(sql, params)
  File "/home/nurmuhammad/.local/lib/python3.10/site-packages/django/db/backends/sqlite3/base.py", line 423, in execute
    return Database.Cursor.execute(self, query, params)
sqlite3.OperationalError: no such table: cart_cart

The above exception was the direct cause of the following exception:

Traceback (most recent call last):
  File "/home/nurmuhammad/.local/lib/python3.10/site-packages/django/core/handlers/exception.py", line 47, in inner
    response = get_response(request)
  File "/home/nurmuhammad/.local/lib/python3.10/site-packages/django/core/handlers/base.py", line 181, in _get_response
    response = wrapped_callback(request, *callback_args, **callback_kwargs)
  File "/home/nurmuhammad/e-commerce/backend/src/apps/cart/views.py", line 24, in add_cart
    cart, created = Cart.objects.get_or_create(user=request.user)
  File "/home/nurmuhammad/.local/lib/python3.10/site-packages/django/db/models/manager.py", line 85, in manager_method
    return getattr(self.get_queryset(), name)(*args, **kwargs)
  File "/home/nurmuhammad/.local/lib/python3.10/site-packages/django/db/models/query.py", line 581, in get_or_create
    return self.get(**kwargs), False
  File "/home/nurmuhammad/.local/lib/python3.10/site-packages/django/db/models/query.py", line 431, in get
    num = len(clone)
  File "/home/nurmuhammad/.local/lib/python3.10/site-packages/django/db/models/query.py", line 262, in __len__
    self._fetch_all()
  File "/home/nurmuhammad/.local/lib/python3.10/site-packages/django/db/models/query.py", line 1324, in _fetch_all
    self._result_cache = list(self._iterable_class(self))
  File "/home/nurmuhammad/.local/lib/python3.10/site-packages/django/db/models/query.py", line 51, in __iter__
    results = compiler.execute_sql(chunked_fetch=self.chunked_fetch, chunk_size=self.chunk_size)
  File "/home/nurmuhammad/.local/lib/python3.10/site-packages/django/db/models/sql/compiler.py", line 1175, in execute_sql
    cursor.execute(sql, params)
  File "/home/nurmuhammad/.local/lib/python3.10/site-packages/django/db/backends/utils.py", line 98, in execute
    return super().execute(sql, params)
  File "/home/nurmuhammad/.local/lib/python3.10/site-packages/django/db/backends/utils.py", line 66, in execute
    return self._execute_with_wrappers(sql, params, many=False, executor=self._execute)
  File "/home/nurmuhammad/.local/lib/python3.10/site-packages/django/db/backends/utils.py", line 75, in _execute_with_wrappers
    return executor(sql, params, many, context)
  File "/home/nurmuhammad/.local/lib/python3.10/site-packages/django/db/backends/utils.py", line 79, in _execute
    with self.db.wrap_database_errors:
  File "/home/nurmuhammad/.local/lib/python3.10/site-packages/django/db/utils.py", line 90, in __exit__
    raise dj_exc_value.with_traceback(traceback) from exc_value
  File "/home/nurmuhammad/.local/lib/python3.10/site-packages/django/db/backends/utils.py", line 84, in _execute
    return self.cursor.execute(sql, params)
  File "/home/nurmuhammad/.local/lib/python3.10/site-packages/django/db/backends/sqlite3/base.py", line 423, in execute
    return Database.Cursor.execute(self, query, params)
django.db.utils.OperationalError: no such table: cart_cart
2023-02-11 19:03:37,205 django.request ERROR    Internal Server Error: /cart/add/cart/
Traceback (most recent call last):
  File "/home/nurmuhammad/.local/lib/python3.10/site-packages/django/db/backends/utils.py", line 84, in _execute
    return self.cursor.execute(sql, params)
  File "/home/nurmuhammad/.local/lib/python3.10/site-packages/django/db/backends/sqlite3/base.py", line 423, in execute
    return Database.Cursor.execute(self, query, params)
sqlite3.OperationalError: no such table: cart_cart

The above exception was the direct cause of the following exception:

Traceback (most recent call last):
  File "/home/nurmuhammad/.local/lib/python3.10/site-packages/django/core/handlers/exception.py", line 47, in inner
    response = get_response(request)
  File "/home/nurmuhammad/.local/lib/python3.10/site-packages/django/core/handlers/base.py", line 181, in _get_response
    response = wrapped_callback(request, *callback_args, **callback_kwargs)
  File "/home/nurmuhammad/e-commerce/backend/src/apps/cart/views.py", line 24, in add_cart
    cart, created = Cart.objects.get_or_create(user=request.user)
  File "/home/nurmuhammad/.local/lib/python3.10/site-packages/django/db/models/manager.py", line 85, in manager_method
    return getattr(self.get_queryset(), name)(*args, **kwargs)
  File "/home/nurmuhammad/.local/lib/python3.10/site-packages/django/db/models/query.py", line 581, in get_or_create
    return self.get(**kwargs), False
  File "/home/nurmuhammad/.local/lib/python3.10/site-packages/django/db/models/query.py", line 431, in get
    num = len(clone)
  File "/home/nurmuhammad/.local/lib/python3.10/site-packages/django/db/models/query.py", line 262, in __len__
    self._fetch_all()
  File "/home/nurmuhammad/.local/lib/python3.10/site-packages/django/db/models/query.py", line 1324, in _fetch_all
    self._result_cache = list(self._iterable_class(self))
  File "/home/nurmuhammad/.local/lib/python3.10/site-packages/django/db/models/query.py", line 51, in __iter__
    results = compiler.execute_sql(chunked_fetch=self.chunked_fetch, chunk_size=self.chunk_size)
  File "/home/nurmuhammad/.local/lib/python3.10/site-packages/django/db/models/sql/compiler.py", line 1175, in execute_sql
    cursor.execute(sql, params)
  File "/home/nurmuhammad/.local/lib/python3.10/site-packages/django/db/backends/utils.py", line 98, in execute
    return super().execute(sql, params)
  File "/home/nurmuhammad/.local/lib/python3.10/site-packages/django/db/backends/utils.py", line 66, in execute
    return self._execute_with_wrappers(sql, params, many=False, executor=self._execute)
  File "/home/nurmuhammad/.local/lib/python3.10/site-packages/django/db/backends/utils.py", line 75, in _execute_with_wrappers
    return executor(sql, params, many, context)
  File "/home/nurmuhammad/.local/lib/python3.10/site-packages/django/db/backends/utils.py", line 79, in _execute
    with self.db.wrap_database_errors:
  File "/home/nurmuhammad/.local/lib/python3.10/site-packages/django/db/utils.py", line 90, in __exit__
    raise dj_exc_value.with_traceback(traceback) from exc_value
  File "/home/nurmuhammad/.local/lib/python3.10/site-packages/django/db/backends/utils.py", line 84, in _execute
    return self.cursor.execute(sql, params)
  File "/home/nurmuhammad/.local/lib/python3.10/site-packages/django/db/backends/sqlite3/base.py", line 423, in execute
    return Database.Cursor.execute(self, query, params)
django.db.utils.OperationalError: no such table: cart_cart
2023-02-12 12:09:57,341 django.request ERROR    Internal Server Error: /cart/add/cart/
Traceback (most recent call last):
  File "/home/nurmuhammad/.local/lib/python3.10/site-packages/django/db/backends/utils.py", line 84, in _execute
    return self.cursor.execute(sql, params)
  File "/home/nurmuhammad/.local/lib/python3.10/site-packages/django/db/backends/sqlite3/base.py", line 423, in execute
    return Database.Cursor.execute(self, query, params)
sqlite3.OperationalError: no such table: cart_cart

The above exception was the direct cause of the following exception:

Traceback (most recent call last):
  File "/home/nurmuhammad/.local/lib/python3.10/site-packages/django/core/handlers/exception.py", line 47, in inner
    response = get_response(request)
  File "/home/nurmuhammad/.local/lib/python3.10/site-packages/django/core/handlers/base.py", line 181, in _get_response
    response = wrapped_callback(request, *callback_args, **callback_kwargs)
  File "/home/nurmuhammad/e-commerce/backend/src/apps/cart/views.py", line 24, in add_cart
    cart, created = Cart.objects.get_or_create(user=request.user)
  File "/home/nurmuhammad/.local/lib/python3.10/site-packages/django/db/models/manager.py", line 85, in manager_method
    return getattr(self.get_queryset(), name)(*args, **kwargs)
  File "/home/nurmuhammad/.local/lib/python3.10/site-packages/django/db/models/query.py", line 581, in get_or_create
    return self.get(**kwargs), False
  File "/home/nurmuhammad/.local/lib/python3.10/site-packages/django/db/models/query.py", line 431, in get
    num = len(clone)
  File "/home/nurmuhammad/.local/lib/python3.10/site-packages/django/db/models/query.py", line 262, in __len__
    self._fetch_all()
  File "/home/nurmuhammad/.local/lib/python3.10/site-packages/django/db/models/query.py", line 1324, in _fetch_all
    self._result_cache = list(self._iterable_class(self))
  File "/home/nurmuhammad/.local/lib/python3.10/site-packages/django/db/models/query.py", line 51, in __iter__
    results = compiler.execute_sql(chunked_fetch=self.chunked_fetch, chunk_size=self.chunk_size)
  File "/home/nurmuhammad/.local/lib/python3.10/site-packages/django/db/models/sql/compiler.py", line 1175, in execute_sql
    cursor.execute(sql, params)
  File "/home/nurmuhammad/.local/lib/python3.10/site-packages/django/db/backends/utils.py", line 98, in execute
    return super().execute(sql, params)
  File "/home/nurmuhammad/.local/lib/python3.10/site-packages/django/db/backends/utils.py", line 66, in execute
    return self._execute_with_wrappers(sql, params, many=False, executor=self._execute)
  File "/home/nurmuhammad/.local/lib/python3.10/site-packages/django/db/backends/utils.py", line 75, in _execute_with_wrappers
    return executor(sql, params, many, context)
  File "/home/nurmuhammad/.local/lib/python3.10/site-packages/django/db/backends/utils.py", line 79, in _execute
    with self.db.wrap_database_errors:
  File "/home/nurmuhammad/.local/lib/python3.10/site-packages/django/db/utils.py", line 90, in __exit__
    raise dj_exc_value.with_traceback(traceback) from exc_value
  File "/home/nurmuhammad/.local/lib/python3.10/site-packages/django/db/backends/utils.py", line 84, in _execute
    return self.cursor.execute(sql, params)
  File "/home/nurmuhammad/.local/lib/python3.10/site-packages/django/db/backends/sqlite3/base.py", line 423, in execute
    return Database.Cursor.execute(self, query, params)
django.db.utils.OperationalError: no such table: cart_cart
2023-02-12 12:10:58,127 django.request ERROR    Internal Server Error: /cart/add/cart/
Traceback (most recent call last):
  File "/home/nurmuhammad/.local/lib/python3.10/site-packages/django/db/backends/utils.py", line 84, in _execute
    return self.cursor.execute(sql, params)
  File "/home/nurmuhammad/.local/lib/python3.10/site-packages/django/db/backends/sqlite3/base.py", line 423, in execute
    return Database.Cursor.execute(self, query, params)
sqlite3.OperationalError: no such table: cart_cart

The above exception was the direct cause of the following exception:

Traceback (most recent call last):
  File "/home/nurmuhammad/.local/lib/python3.10/site-packages/django/core/handlers/exception.py", line 47, in inner
    response = get_response(request)
  File "/home/nurmuhammad/.local/lib/python3.10/site-packages/django/core/handlers/base.py", line 181, in _get_response
    response = wrapped_callback(request, *callback_args, **callback_kwargs)
  File "/home/nurmuhammad/e-commerce/backend/src/apps/cart/views.py", line 24, in add_cart
    cart, created = Cart.objects.get_or_create(user=request.user)
  File "/home/nurmuhammad/.local/lib/python3.10/site-packages/django/db/models/manager.py", line 85, in manager_method
    return getattr(self.get_queryset(), name)(*args, **kwargs)
  File "/home/nurmuhammad/.local/lib/python3.10/site-packages/django/db/models/query.py", line 581, in get_or_create
    return self.get(**kwargs), False
  File "/home/nurmuhammad/.local/lib/python3.10/site-packages/django/db/models/query.py", line 431, in get
    num = len(clone)
  File "/home/nurmuhammad/.local/lib/python3.10/site-packages/django/db/models/query.py", line 262, in __len__
    self._fetch_all()
  File "/home/nurmuhammad/.local/lib/python3.10/site-packages/django/db/models/query.py", line 1324, in _fetch_all
    self._result_cache = list(self._iterable_class(self))
  File "/home/nurmuhammad/.local/lib/python3.10/site-packages/django/db/models/query.py", line 51, in __iter__
    results = compiler.execute_sql(chunked_fetch=self.chunked_fetch, chunk_size=self.chunk_size)
  File "/home/nurmuhammad/.local/lib/python3.10/site-packages/django/db/models/sql/compiler.py", line 1175, in execute_sql
    cursor.execute(sql, params)
  File "/home/nurmuhammad/.local/lib/python3.10/site-packages/django/db/backends/utils.py", line 98, in execute
    return super().execute(sql, params)
  File "/home/nurmuhammad/.local/lib/python3.10/site-packages/django/db/backends/utils.py", line 66, in execute
    return self._execute_with_wrappers(sql, params, many=False, executor=self._execute)
  File "/home/nurmuhammad/.local/lib/python3.10/site-packages/django/db/backends/utils.py", line 75, in _execute_with_wrappers
    return executor(sql, params, many, context)
  File "/home/nurmuhammad/.local/lib/python3.10/site-packages/django/db/backends/utils.py", line 79, in _execute
    with self.db.wrap_database_errors:
  File "/home/nurmuhammad/.local/lib/python3.10/site-packages/django/db/utils.py", line 90, in __exit__
    raise dj_exc_value.with_traceback(traceback) from exc_value
  File "/home/nurmuhammad/.local/lib/python3.10/site-packages/django/db/backends/utils.py", line 84, in _execute
    return self.cursor.execute(sql, params)
  File "/home/nurmuhammad/.local/lib/python3.10/site-packages/django/db/backends/sqlite3/base.py", line 423, in execute
    return Database.Cursor.execute(self, query, params)
django.db.utils.OperationalError: no such table: cart_cart
2023-02-12 15:12:41,134 django.request ERROR    Internal Server Error: /login/
Traceback (most recent call last):
  File "/home/nurmuhammad/.local/lib/python3.10/site-packages/django/template/base.py", line 470, in parse
    compile_func = self.tags[command]
KeyError: 'form.as_p'

During handling of the above exception, another exception occurred:

Traceback (most recent call last):
  File "/home/nurmuhammad/.local/lib/python3.10/site-packages/django/core/handlers/exception.py", line 47, in inner
    response = get_response(request)
  File "/home/nurmuhammad/.local/lib/python3.10/site-packages/django/core/handlers/base.py", line 181, in _get_response
    response = wrapped_callback(request, *callback_args, **callback_kwargs)
  File "/home/nurmuhammad/e-commerce/backend/src/apps/accounts/views/login.py", line 19, in _wrapped_view
    return view_func(request, *args, **kwargs)
  File "/home/nurmuhammad/e-commerce/backend/src/apps/accounts/views/login.py", line 53, in login
    return render(
  File "/home/nurmuhammad/.local/lib/python3.10/site-packages/django/shortcuts.py", line 19, in render
    content = loader.render_to_string(template_name, context, request, using=using)
  File "/home/nurmuhammad/.local/lib/python3.10/site-packages/django/template/loader.py", line 61, in render_to_string
    template = get_template(template_name, using=using)
  File "/home/nurmuhammad/.local/lib/python3.10/site-packages/django/template/loader.py", line 15, in get_template
    return engine.get_template(template_name)
  File "/home/nurmuhammad/.local/lib/python3.10/site-packages/django/template/backends/django.py", line 34, in get_template
    return Template(self.engine.get_template(template_name), self)
  File "/home/nurmuhammad/.local/lib/python3.10/site-packages/django/template/engine.py", line 143, in get_template
    template, origin = self.find_template(template_name)
  File "/home/nurmuhammad/.local/lib/python3.10/site-packages/django/template/engine.py", line 125, in find_template
    template = loader.get_template(name, skip=skip)
  File "/home/nurmuhammad/.local/lib/python3.10/site-packages/django/template/loaders/base.py", line 29, in get_template
    return Template(
  File "/home/nurmuhammad/.local/lib/python3.10/site-packages/django/template/base.py", line 155, in __init__
    self.nodelist = self.compile_nodelist()
  File "/home/nurmuhammad/.local/lib/python3.10/site-packages/django/template/base.py", line 193, in compile_nodelist
    return parser.parse()
  File "/home/nurmuhammad/.local/lib/python3.10/site-packages/django/template/base.py", line 478, in parse
    raise self.error(token, e)
  File "/home/nurmuhammad/.local/lib/python3.10/site-packages/django/template/base.py", line 476, in parse
    compiled_result = compile_func(self, token)
  File "/home/nurmuhammad/.local/lib/python3.10/site-packages/django/template/loader_tags.py", line 278, in do_extends
    nodelist = parser.parse()
  File "/home/nurmuhammad/.local/lib/python3.10/site-packages/django/template/base.py", line 478, in parse
    raise self.error(token, e)
  File "/home/nurmuhammad/.local/lib/python3.10/site-packages/django/template/base.py", line 476, in parse
    compiled_result = compile_func(self, token)
  File "/home/nurmuhammad/.local/lib/python3.10/site-packages/django/template/loader_tags.py", line 216, in do_block
    nodelist = parser.parse(('endblock',))
  File "/home/nurmuhammad/.local/lib/python3.10/site-packages/django/template/base.py", line 472, in parse
    self.invalid_block_tag(token, command, parse_until)
  File "/home/nurmuhammad/.local/lib/python3.10/site-packages/django/template/base.py", line 522, in invalid_block_tag
    raise self.error(
django.template.exceptions.TemplateSyntaxError: Invalid block tag on line 32: 'form.as_p', expected 'endblock'. Did you forget to register or load this tag?
2023-02-12 15:13:02,574 django.request ERROR    Internal Server Error: /login/
Traceback (most recent call last):
  File "/home/nurmuhammad/.local/lib/python3.10/site-packages/django/template/base.py", line 470, in parse
    compile_func = self.tags[command]
KeyError: 'form.as_p'

During handling of the above exception, another exception occurred:

Traceback (most recent call last):
  File "/home/nurmuhammad/.local/lib/python3.10/site-packages/django/core/handlers/exception.py", line 47, in inner
    response = get_response(request)
  File "/home/nurmuhammad/.local/lib/python3.10/site-packages/django/core/handlers/base.py", line 181, in _get_response
    response = wrapped_callback(request, *callback_args, **callback_kwargs)
  File "/home/nurmuhammad/e-commerce/backend/src/apps/accounts/views/login.py", line 19, in _wrapped_view
    return view_func(request, *args, **kwargs)
  File "/home/nurmuhammad/e-commerce/backend/src/apps/accounts/views/login.py", line 53, in login
    return render(
  File "/home/nurmuhammad/.local/lib/python3.10/site-packages/django/shortcuts.py", line 19, in render
    content = loader.render_to_string(template_name, context, request, using=using)
  File "/home/nurmuhammad/.local/lib/python3.10/site-packages/django/template/loader.py", line 61, in render_to_string
    template = get_template(template_name, using=using)
  File "/home/nurmuhammad/.local/lib/python3.10/site-packages/django/template/loader.py", line 15, in get_template
    return engine.get_template(template_name)
  File "/home/nurmuhammad/.local/lib/python3.10/site-packages/django/template/backends/django.py", line 34, in get_template
    return Template(self.engine.get_template(template_name), self)
  File "/home/nurmuhammad/.local/lib/python3.10/site-packages/django/template/engine.py", line 143, in get_template
    template, origin = self.find_template(template_name)
  File "/home/nurmuhammad/.local/lib/python3.10/site-packages/django/template/engine.py", line 125, in find_template
    template = loader.get_template(name, skip=skip)
  File "/home/nurmuhammad/.local/lib/python3.10/site-packages/django/template/loaders/base.py", line 29, in get_template
    return Template(
  File "/home/nurmuhammad/.local/lib/python3.10/site-packages/django/template/base.py", line 155, in __init__
    self.nodelist = self.compile_nodelist()
  File "/home/nurmuhammad/.local/lib/python3.10/site-packages/django/template/base.py", line 193, in compile_nodelist
    return parser.parse()
  File "/home/nurmuhammad/.local/lib/python3.10/site-packages/django/template/base.py", line 478, in parse
    raise self.error(token, e)
  File "/home/nurmuhammad/.local/lib/python3.10/site-packages/django/template/base.py", line 476, in parse
    compiled_result = compile_func(self, token)
  File "/home/nurmuhammad/.local/lib/python3.10/site-packages/django/template/loader_tags.py", line 278, in do_extends
    nodelist = parser.parse()
  File "/home/nurmuhammad/.local/lib/python3.10/site-packages/django/template/base.py", line 478, in parse
    raise self.error(token, e)
  File "/home/nurmuhammad/.local/lib/python3.10/site-packages/django/template/base.py", line 476, in parse
    compiled_result = compile_func(self, token)
  File "/home/nurmuhammad/.local/lib/python3.10/site-packages/django/template/loader_tags.py", line 216, in do_block
    nodelist = parser.parse(('endblock',))
  File "/home/nurmuhammad/.local/lib/python3.10/site-packages/django/template/base.py", line 472, in parse
    self.invalid_block_tag(token, command, parse_until)
  File "/home/nurmuhammad/.local/lib/python3.10/site-packages/django/template/base.py", line 522, in invalid_block_tag
    raise self.error(
django.template.exceptions.TemplateSyntaxError: Invalid block tag on line 32: 'form.as_p', expected 'endblock'. Did you forget to register or load this tag?
2023-02-12 15:13:32,828 django.request ERROR    Internal Server Error: /login/
Traceback (most recent call last):
  File "/home/nurmuhammad/.local/lib/python3.10/site-packages/django/template/backends/django.py", line 34, in get_template
    return Template(self.engine.get_template(template_name), self)
  File "/home/nurmuhammad/.local/lib/python3.10/site-packages/django/template/engine.py", line 143, in get_template
    template, origin = self.find_template(template_name)
  File "/home/nurmuhammad/.local/lib/python3.10/site-packages/django/template/engine.py", line 129, in find_template
    raise TemplateDoesNotExist(name, tried=tried)
django.template.exceptions.TemplateDoesNotExist: captcha/widget_v2_checkbox.html

The above exception was the direct cause of the following exception:

Traceback (most recent call last):
  File "/home/nurmuhammad/.local/lib/python3.10/site-packages/django/template/backends/django.py", line 61, in render
    return self.template.render(context)
  File "/home/nurmuhammad/.local/lib/python3.10/site-packages/django/template/base.py", line 170, in render
    return self._render(context)
  File "/home/nurmuhammad/.local/lib/python3.10/site-packages/django/template/base.py", line 162, in _render
    return self.nodelist.render(context)
  File "/home/nurmuhammad/.local/lib/python3.10/site-packages/django/template/base.py", line 938, in render
    bit = node.render_annotated(context)
  File "/home/nurmuhammad/.local/lib/python3.10/site-packages/django/template/base.py", line 905, in render_annotated
    return self.render(context)
  File "/home/nurmuhammad/.local/lib/python3.10/site-packages/django/template/loader_tags.py", line 150, in render
    return compiled_parent._render(context)
  File "/home/nurmuhammad/.local/lib/python3.10/site-packages/django/template/base.py", line 162, in _render
    return self.nodelist.render(context)
  File "/home/nurmuhammad/.local/lib/python3.10/site-packages/django/template/base.py", line 938, in render
    bit = node.render_annotated(context)
  File "/home/nurmuhammad/.local/lib/python3.10/site-packages/django/template/base.py", line 905, in render_annotated
    return self.render(context)
  File "/home/nurmuhammad/.local/lib/python3.10/site-packages/django/template/loader_tags.py", line 62, in render
    result = block.nodelist.render(context)
  File "/home/nurmuhammad/.local/lib/python3.10/site-packages/django/template/base.py", line 938, in render
    bit = node.render_annotated(context)
  File "/home/nurmuhammad/.local/lib/python3.10/site-packages/django/template/base.py", line 905, in render_annotated
    return self.render(context)
  File "/home/nurmuhammad/.local/lib/python3.10/site-packages/django/template/base.py", line 988, in render
    output = self.filter_expression.resolve(context)
  File "/home/nurmuhammad/.local/lib/python3.10/site-packages/django/template/base.py", line 671, in resolve
    obj = self.var.resolve(context)
  File "/home/nurmuhammad/.local/lib/python3.10/site-packages/django/template/base.py", line 796, in resolve
    value = self._resolve_lookup(context)
  File "/home/nurmuhammad/.local/lib/python3.10/site-packages/django/template/base.py", line 858, in _resolve_lookup
    current = current()
  File "/home/nurmuhammad/.local/lib/python3.10/site-packages/django/forms/forms.py", line 290, in as_p
    return self._html_output(
  File "/home/nurmuhammad/.local/lib/python3.10/site-packages/django/forms/forms.py", line 227, in _html_output
    output.append(normal_row % {
  File "/home/nurmuhammad/.local/lib/python3.10/site-packages/django/utils/html.py", line 376, in <lambda>
    klass.__str__ = lambda self: mark_safe(klass_str(self))
  File "/home/nurmuhammad/.local/lib/python3.10/site-packages/django/forms/boundfield.py", line 34, in __str__
    return self.as_widget()
  File "/home/nurmuhammad/.local/lib/python3.10/site-packages/django/forms/boundfield.py", line 93, in as_widget
    return widget.render(
  File "/home/nurmuhammad/.local/lib/python3.10/site-packages/django/forms/widgets.py", line 247, in render
    return self._render(self.template_name, context, renderer)
  File "/home/nurmuhammad/.local/lib/python3.10/site-packages/django/forms/widgets.py", line 252, in _render
    return mark_safe(renderer.render(template_name, context))
  File "/home/nurmuhammad/.local/lib/python3.10/site-packages/django/forms/renderers.py", line 24, in render
    template = self.get_template(template_name)
  File "/home/nurmuhammad/.local/lib/python3.10/site-packages/django/forms/renderers.py", line 30, in get_template
    return self.engine.get_template(template_name)
  File "/home/nurmuhammad/.local/lib/python3.10/site-packages/django/template/backends/django.py", line 36, in get_template
    reraise(exc, self)
  File "/home/nurmuhammad/.local/lib/python3.10/site-packages/django/template/backends/django.py", line 84, in reraise
    raise new from exc
django.template.exceptions.TemplateDoesNotExist: captcha/widget_v2_checkbox.html

The above exception was the direct cause of the following exception:

Traceback (most recent call last):
  File "/home/nurmuhammad/.local/lib/python3.10/site-packages/django/core/handlers/exception.py", line 47, in inner
    response = get_response(request)
  File "/home/nurmuhammad/.local/lib/python3.10/site-packages/django/core/handlers/base.py", line 181, in _get_response
    response = wrapped_callback(request, *callback_args, **callback_kwargs)
  File "/home/nurmuhammad/e-commerce/backend/src/apps/accounts/views/login.py", line 19, in _wrapped_view
    return view_func(request, *args, **kwargs)
  File "/home/nurmuhammad/e-commerce/backend/src/apps/accounts/views/login.py", line 53, in login
    return render(
  File "/home/nurmuhammad/.local/lib/python3.10/site-packages/django/shortcuts.py", line 19, in render
    content = loader.render_to_string(template_name, context, request, using=using)
  File "/home/nurmuhammad/.local/lib/python3.10/site-packages/django/template/loader.py", line 62, in render_to_string
    return template.render(context, request)
  File "/home/nurmuhammad/.local/lib/python3.10/site-packages/django/template/backends/django.py", line 63, in render
    reraise(exc, self.backend)
  File "/home/nurmuhammad/.local/lib/python3.10/site-packages/django/template/backends/django.py", line 84, in reraise
    raise new from exc
django.template.exceptions.TemplateDoesNotExist: captcha/widget_v2_checkbox.html
2023-02-12 15:13:33,794 django.request ERROR    Internal Server Error: /login/
Traceback (most recent call last):
  File "/home/nurmuhammad/.local/lib/python3.10/site-packages/django/template/backends/django.py", line 34, in get_template
    return Template(self.engine.get_template(template_name), self)
  File "/home/nurmuhammad/.local/lib/python3.10/site-packages/django/template/engine.py", line 143, in get_template
    template, origin = self.find_template(template_name)
  File "/home/nurmuhammad/.local/lib/python3.10/site-packages/django/template/engine.py", line 129, in find_template
    raise TemplateDoesNotExist(name, tried=tried)
django.template.exceptions.TemplateDoesNotExist: captcha/widget_v2_checkbox.html

The above exception was the direct cause of the following exception:

Traceback (most recent call last):
  File "/home/nurmuhammad/.local/lib/python3.10/site-packages/django/template/backends/django.py", line 61, in render
    return self.template.render(context)
  File "/home/nurmuhammad/.local/lib/python3.10/site-packages/django/template/base.py", line 170, in render
    return self._render(context)
  File "/home/nurmuhammad/.local/lib/python3.10/site-packages/django/template/base.py", line 162, in _render
    return self.nodelist.render(context)
  File "/home/nurmuhammad/.local/lib/python3.10/site-packages/django/template/base.py", line 938, in render
    bit = node.render_annotated(context)
  File "/home/nurmuhammad/.local/lib/python3.10/site-packages/django/template/base.py", line 905, in render_annotated
    return self.render(context)
  File "/home/nurmuhammad/.local/lib/python3.10/site-packages/django/template/loader_tags.py", line 150, in render
    return compiled_parent._render(context)
  File "/home/nurmuhammad/.local/lib/python3.10/site-packages/django/template/base.py", line 162, in _render
    return self.nodelist.render(context)
  File "/home/nurmuhammad/.local/lib/python3.10/site-packages/django/template/base.py", line 938, in render
    bit = node.render_annotated(context)
  File "/home/nurmuhammad/.local/lib/python3.10/site-packages/django/template/base.py", line 905, in render_annotated
    return self.render(context)
  File "/home/nurmuhammad/.local/lib/python3.10/site-packages/django/template/loader_tags.py", line 62, in render
    result = block.nodelist.render(context)
  File "/home/nurmuhammad/.local/lib/python3.10/site-packages/django/template/base.py", line 938, in render
    bit = node.render_annotated(context)
  File "/home/nurmuhammad/.local/lib/python3.10/site-packages/django/template/base.py", line 905, in render_annotated
    return self.render(context)
  File "/home/nurmuhammad/.local/lib/python3.10/site-packages/django/template/base.py", line 988, in render
    output = self.filter_expression.resolve(context)
  File "/home/nurmuhammad/.local/lib/python3.10/site-packages/django/template/base.py", line 671, in resolve
    obj = self.var.resolve(context)
  File "/home/nurmuhammad/.local/lib/python3.10/site-packages/django/template/base.py", line 796, in resolve
    value = self._resolve_lookup(context)
  File "/home/nurmuhammad/.local/lib/python3.10/site-packages/django/template/base.py", line 858, in _resolve_lookup
    current = current()
  File "/home/nurmuhammad/.local/lib/python3.10/site-packages/django/forms/forms.py", line 290, in as_p
    return self._html_output(
  File "/home/nurmuhammad/.local/lib/python3.10/site-packages/django/forms/forms.py", line 227, in _html_output
    output.append(normal_row % {
  File "/home/nurmuhammad/.local/lib/python3.10/site-packages/django/utils/html.py", line 376, in <lambda>
    klass.__str__ = lambda self: mark_safe(klass_str(self))
  File "/home/nurmuhammad/.local/lib/python3.10/site-packages/django/forms/boundfield.py", line 34, in __str__
    return self.as_widget()
  File "/home/nurmuhammad/.local/lib/python3.10/site-packages/django/forms/boundfield.py", line 93, in as_widget
    return widget.render(
  File "/home/nurmuhammad/.local/lib/python3.10/site-packages/django/forms/widgets.py", line 247, in render
    return self._render(self.template_name, context, renderer)
  File "/home/nurmuhammad/.local/lib/python3.10/site-packages/django/forms/widgets.py", line 252, in _render
    return mark_safe(renderer.render(template_name, context))
  File "/home/nurmuhammad/.local/lib/python3.10/site-packages/django/forms/renderers.py", line 24, in render
    template = self.get_template(template_name)
  File "/home/nurmuhammad/.local/lib/python3.10/site-packages/django/forms/renderers.py", line 30, in get_template
    return self.engine.get_template(template_name)
  File "/home/nurmuhammad/.local/lib/python3.10/site-packages/django/template/backends/django.py", line 36, in get_template
    reraise(exc, self)
  File "/home/nurmuhammad/.local/lib/python3.10/site-packages/django/template/backends/django.py", line 84, in reraise
    raise new from exc
django.template.exceptions.TemplateDoesNotExist: captcha/widget_v2_checkbox.html

The above exception was the direct cause of the following exception:

Traceback (most recent call last):
  File "/home/nurmuhammad/.local/lib/python3.10/site-packages/django/core/handlers/exception.py", line 47, in inner
    response = get_response(request)
  File "/home/nurmuhammad/.local/lib/python3.10/site-packages/django/core/handlers/base.py", line 181, in _get_response
    response = wrapped_callback(request, *callback_args, **callback_kwargs)
  File "/home/nurmuhammad/e-commerce/backend/src/apps/accounts/views/login.py", line 19, in _wrapped_view
    return view_func(request, *args, **kwargs)
  File "/home/nurmuhammad/e-commerce/backend/src/apps/accounts/views/login.py", line 53, in login
    return render(
  File "/home/nurmuhammad/.local/lib/python3.10/site-packages/django/shortcuts.py", line 19, in render
    content = loader.render_to_string(template_name, context, request, using=using)
  File "/home/nurmuhammad/.local/lib/python3.10/site-packages/django/template/loader.py", line 62, in render_to_string
    return template.render(context, request)
  File "/home/nurmuhammad/.local/lib/python3.10/site-packages/django/template/backends/django.py", line 63, in render
    reraise(exc, self.backend)
  File "/home/nurmuhammad/.local/lib/python3.10/site-packages/django/template/backends/django.py", line 84, in reraise
    raise new from exc
django.template.exceptions.TemplateDoesNotExist: captcha/widget_v2_checkbox.html
2023-02-12 15:15:46,349 django.request ERROR    Internal Server Error: /login/
Traceback (most recent call last):
  File "/home/nurmuhammad/.local/lib/python3.10/site-packages/django/template/backends/django.py", line 34, in get_template
    return Template(self.engine.get_template(template_name), self)
  File "/home/nurmuhammad/.local/lib/python3.10/site-packages/django/template/engine.py", line 143, in get_template
    template, origin = self.find_template(template_name)
  File "/home/nurmuhammad/.local/lib/python3.10/site-packages/django/template/engine.py", line 129, in find_template
    raise TemplateDoesNotExist(name, tried=tried)
django.template.exceptions.TemplateDoesNotExist: captcha/widget_v2_checkbox.html

The above exception was the direct cause of the following exception:

Traceback (most recent call last):
  File "/home/nurmuhammad/.local/lib/python3.10/site-packages/django/template/backends/django.py", line 61, in render
    return self.template.render(context)
  File "/home/nurmuhammad/.local/lib/python3.10/site-packages/django/template/base.py", line 170, in render
    return self._render(context)
  File "/home/nurmuhammad/.local/lib/python3.10/site-packages/django/template/base.py", line 162, in _render
    return self.nodelist.render(context)
  File "/home/nurmuhammad/.local/lib/python3.10/site-packages/django/template/base.py", line 938, in render
    bit = node.render_annotated(context)
  File "/home/nurmuhammad/.local/lib/python3.10/site-packages/django/template/base.py", line 905, in render_annotated
    return self.render(context)
  File "/home/nurmuhammad/.local/lib/python3.10/site-packages/django/template/loader_tags.py", line 150, in render
    return compiled_parent._render(context)
  File "/home/nurmuhammad/.local/lib/python3.10/site-packages/django/template/base.py", line 162, in _render
    return self.nodelist.render(context)
  File "/home/nurmuhammad/.local/lib/python3.10/site-packages/django/template/base.py", line 938, in render
    bit = node.render_annotated(context)
  File "/home/nurmuhammad/.local/lib/python3.10/site-packages/django/template/base.py", line 905, in render_annotated
    return self.render(context)
  File "/home/nurmuhammad/.local/lib/python3.10/site-packages/django/template/loader_tags.py", line 62, in render
    result = block.nodelist.render(context)
  File "/home/nurmuhammad/.local/lib/python3.10/site-packages/django/template/base.py", line 938, in render
    bit = node.render_annotated(context)
  File "/home/nurmuhammad/.local/lib/python3.10/site-packages/django/template/base.py", line 905, in render_annotated
    return self.render(context)
  File "/home/nurmuhammad/.local/lib/python3.10/site-packages/django/template/base.py", line 988, in render
    output = self.filter_expression.resolve(context)
  File "/home/nurmuhammad/.local/lib/python3.10/site-packages/django/template/base.py", line 671, in resolve
    obj = self.var.resolve(context)
  File "/home/nurmuhammad/.local/lib/python3.10/site-packages/django/template/base.py", line 796, in resolve
    value = self._resolve_lookup(context)
  File "/home/nurmuhammad/.local/lib/python3.10/site-packages/django/template/base.py", line 858, in _resolve_lookup
    current = current()
  File "/home/nurmuhammad/.local/lib/python3.10/site-packages/django/forms/forms.py", line 290, in as_p
    return self._html_output(
  File "/home/nurmuhammad/.local/lib/python3.10/site-packages/django/forms/forms.py", line 227, in _html_output
    output.append(normal_row % {
  File "/home/nurmuhammad/.local/lib/python3.10/site-packages/django/utils/html.py", line 376, in <lambda>
    klass.__str__ = lambda self: mark_safe(klass_str(self))
  File "/home/nurmuhammad/.local/lib/python3.10/site-packages/django/forms/boundfield.py", line 34, in __str__
    return self.as_widget()
  File "/home/nurmuhammad/.local/lib/python3.10/site-packages/django/forms/boundfield.py", line 93, in as_widget
    return widget.render(
  File "/home/nurmuhammad/.local/lib/python3.10/site-packages/django/forms/widgets.py", line 247, in render
    return self._render(self.template_name, context, renderer)
  File "/home/nurmuhammad/.local/lib/python3.10/site-packages/django/forms/widgets.py", line 252, in _render
    return mark_safe(renderer.render(template_name, context))
  File "/home/nurmuhammad/.local/lib/python3.10/site-packages/django/forms/renderers.py", line 24, in render
    template = self.get_template(template_name)
  File "/home/nurmuhammad/.local/lib/python3.10/site-packages/django/forms/renderers.py", line 30, in get_template
    return self.engine.get_template(template_name)
  File "/home/nurmuhammad/.local/lib/python3.10/site-packages/django/template/backends/django.py", line 36, in get_template
    reraise(exc, self)
  File "/home/nurmuhammad/.local/lib/python3.10/site-packages/django/template/backends/django.py", line 84, in reraise
    raise new from exc
django.template.exceptions.TemplateDoesNotExist: captcha/widget_v2_checkbox.html

The above exception was the direct cause of the following exception:

Traceback (most recent call last):
  File "/home/nurmuhammad/.local/lib/python3.10/site-packages/django/core/handlers/exception.py", line 47, in inner
    response = get_response(request)
  File "/home/nurmuhammad/.local/lib/python3.10/site-packages/django/core/handlers/base.py", line 181, in _get_response
    response = wrapped_callback(request, *callback_args, **callback_kwargs)
  File "/home/nurmuhammad/e-commerce/backend/src/apps/accounts/views/login.py", line 19, in _wrapped_view
    return view_func(request, *args, **kwargs)
  File "/home/nurmuhammad/e-commerce/backend/src/apps/accounts/views/login.py", line 53, in login
    return render(
  File "/home/nurmuhammad/.local/lib/python3.10/site-packages/django/shortcuts.py", line 19, in render
    content = loader.render_to_string(template_name, context, request, using=using)
  File "/home/nurmuhammad/.local/lib/python3.10/site-packages/django/template/loader.py", line 62, in render_to_string
    return template.render(context, request)
  File "/home/nurmuhammad/.local/lib/python3.10/site-packages/django/template/backends/django.py", line 63, in render
    reraise(exc, self.backend)
  File "/home/nurmuhammad/.local/lib/python3.10/site-packages/django/template/backends/django.py", line 84, in reraise
    raise new from exc
django.template.exceptions.TemplateDoesNotExist: captcha/widget_v2_checkbox.html
2023-02-12 15:18:03,223 django.request ERROR    Internal Server Error: /login/
Traceback (most recent call last):
  File "/usr/lib/python3.10/urllib/request.py", line 1348, in do_open
    h.request(req.get_method(), req.selector, req.data, headers,
  File "/usr/lib/python3.10/http/client.py", line 1282, in request
    self._send_request(method, url, body, headers, encode_chunked)
  File "/usr/lib/python3.10/http/client.py", line 1328, in _send_request
    self.endheaders(body, encode_chunked=encode_chunked)
  File "/usr/lib/python3.10/http/client.py", line 1277, in endheaders
    self._send_output(message_body, encode_chunked=encode_chunked)
  File "/usr/lib/python3.10/http/client.py", line 1037, in _send_output
    self.send(msg)
  File "/usr/lib/python3.10/http/client.py", line 975, in send
    self.connect()
  File "/usr/lib/python3.10/http/client.py", line 1447, in connect
    super().connect()
  File "/usr/lib/python3.10/http/client.py", line 941, in connect
    self.sock = self._create_connection(
  File "/usr/lib/python3.10/socket.py", line 845, in create_connection
    raise err
  File "/usr/lib/python3.10/socket.py", line 833, in create_connection
    sock.connect(sa)
OSError: [Errno 101] Network is unreachable

During handling of the above exception, another exception occurred:

Traceback (most recent call last):
  File "/home/nurmuhammad/.local/lib/python3.10/site-packages/django/core/handlers/exception.py", line 47, in inner
    response = get_response(request)
  File "/home/nurmuhammad/.local/lib/python3.10/site-packages/django/core/handlers/base.py", line 181, in _get_response
    response = wrapped_callback(request, *callback_args, **callback_kwargs)
  File "/home/nurmuhammad/e-commerce/backend/src/apps/accounts/views/login.py", line 19, in _wrapped_view
    return view_func(request, *args, **kwargs)
  File "/home/nurmuhammad/e-commerce/backend/src/apps/accounts/views/login.py", line 33, in login
    if form.is_valid():
  File "/home/nurmuhammad/.local/lib/python3.10/site-packages/django/forms/forms.py", line 175, in is_valid
    return self.is_bound and not self.errors
  File "/home/nurmuhammad/.local/lib/python3.10/site-packages/django/forms/forms.py", line 170, in errors
    self.full_clean()
  File "/home/nurmuhammad/.local/lib/python3.10/site-packages/django/forms/forms.py", line 372, in full_clean
    self._clean_fields()
  File "/home/nurmuhammad/.local/lib/python3.10/site-packages/django/forms/forms.py", line 390, in _clean_fields
    value = field.clean(value)
  File "/home/nurmuhammad/.local/lib/python3.10/site-packages/django/forms/fields.py", line 150, in clean
    self.validate(value)
  File "/home/nurmuhammad/.local/lib/python3.10/site-packages/captcha/fields.py", line 69, in validate
    check_captcha = client.submit(
  File "/home/nurmuhammad/.local/lib/python3.10/site-packages/captcha/client.py", line 63, in submit
    response = recaptcha_request(params)
  File "/home/nurmuhammad/.local/lib/python3.10/site-packages/captcha/client.py", line 38, in recaptcha_request
    return opener.open(
  File "/usr/lib/python3.10/urllib/request.py", line 519, in open
    response = self._open(req, data)
  File "/usr/lib/python3.10/urllib/request.py", line 536, in _open
    result = self._call_chain(self.handle_open, protocol, protocol +
  File "/usr/lib/python3.10/urllib/request.py", line 496, in _call_chain
    result = func(*args)
  File "/usr/lib/python3.10/urllib/request.py", line 1391, in https_open
    return self.do_open(http.client.HTTPSConnection, req,
  File "/usr/lib/python3.10/urllib/request.py", line 1351, in do_open
    raise URLError(err)
urllib.error.URLError: <urlopen error [Errno 101] Network is unreachable>
2023-02-14 16:44:40,414 django.request ERROR    Internal Server Error: /cart/add/cart/
Traceback (most recent call last):
  File "/home/nurmuhammad/.local/lib/python3.10/site-packages/django/db/backends/utils.py", line 84, in _execute
    return self.cursor.execute(sql, params)
  File "/home/nurmuhammad/.local/lib/python3.10/site-packages/django/db/backends/sqlite3/base.py", line 423, in execute
    return Database.Cursor.execute(self, query, params)
sqlite3.OperationalError: no such table: cart_cart

The above exception was the direct cause of the following exception:

Traceback (most recent call last):
  File "/home/nurmuhammad/.local/lib/python3.10/site-packages/django/core/handlers/exception.py", line 47, in inner
    response = get_response(request)
  File "/home/nurmuhammad/.local/lib/python3.10/site-packages/django/core/handlers/base.py", line 181, in _get_response
    response = wrapped_callback(request, *callback_args, **callback_kwargs)
  File "/home/nurmuhammad/e-commerce/backend/src/apps/cart/views.py", line 24, in add_cart
    cart, created = Cart.objects.get_or_create(user=request.user)
  File "/home/nurmuhammad/.local/lib/python3.10/site-packages/django/db/models/manager.py", line 85, in manager_method
    return getattr(self.get_queryset(), name)(*args, **kwargs)
  File "/home/nurmuhammad/.local/lib/python3.10/site-packages/django/db/models/query.py", line 581, in get_or_create
    return self.get(**kwargs), False
  File "/home/nurmuhammad/.local/lib/python3.10/site-packages/django/db/models/query.py", line 431, in get
    num = len(clone)
  File "/home/nurmuhammad/.local/lib/python3.10/site-packages/django/db/models/query.py", line 262, in __len__
    self._fetch_all()
  File "/home/nurmuhammad/.local/lib/python3.10/site-packages/django/db/models/query.py", line 1324, in _fetch_all
    self._result_cache = list(self._iterable_class(self))
  File "/home/nurmuhammad/.local/lib/python3.10/site-packages/django/db/models/query.py", line 51, in __iter__
    results = compiler.execute_sql(chunked_fetch=self.chunked_fetch, chunk_size=self.chunk_size)
  File "/home/nurmuhammad/.local/lib/python3.10/site-packages/django/db/models/sql/compiler.py", line 1175, in execute_sql
    cursor.execute(sql, params)
  File "/home/nurmuhammad/.local/lib/python3.10/site-packages/django/db/backends/utils.py", line 98, in execute
    return super().execute(sql, params)
  File "/home/nurmuhammad/.local/lib/python3.10/site-packages/django/db/backends/utils.py", line 66, in execute
    return self._execute_with_wrappers(sql, params, many=False, executor=self._execute)
  File "/home/nurmuhammad/.local/lib/python3.10/site-packages/django/db/backends/utils.py", line 75, in _execute_with_wrappers
    return executor(sql, params, many, context)
  File "/home/nurmuhammad/.local/lib/python3.10/site-packages/django/db/backends/utils.py", line 79, in _execute
    with self.db.wrap_database_errors:
  File "/home/nurmuhammad/.local/lib/python3.10/site-packages/django/db/utils.py", line 90, in __exit__
    raise dj_exc_value.with_traceback(traceback) from exc_value
  File "/home/nurmuhammad/.local/lib/python3.10/site-packages/django/db/backends/utils.py", line 84, in _execute
    return self.cursor.execute(sql, params)
  File "/home/nurmuhammad/.local/lib/python3.10/site-packages/django/db/backends/sqlite3/base.py", line 423, in execute
    return Database.Cursor.execute(self, query, params)
django.db.utils.OperationalError: no such table: cart_cart
2023-02-14 16:55:31,490 django.request ERROR    Internal Server Error: /cart/add/cart/
Traceback (most recent call last):
  File "/home/nurmuhammad/.local/lib/python3.10/site-packages/django/db/backends/utils.py", line 84, in _execute
    return self.cursor.execute(sql, params)
  File "/home/nurmuhammad/.local/lib/python3.10/site-packages/django/db/backends/sqlite3/base.py", line 423, in execute
    return Database.Cursor.execute(self, query, params)
sqlite3.OperationalError: no such table: cart_cart

The above exception was the direct cause of the following exception:

Traceback (most recent call last):
  File "/home/nurmuhammad/.local/lib/python3.10/site-packages/django/core/handlers/exception.py", line 47, in inner
    response = get_response(request)
  File "/home/nurmuhammad/.local/lib/python3.10/site-packages/django/core/handlers/base.py", line 181, in _get_response
    response = wrapped_callback(request, *callback_args, **callback_kwargs)
  File "/home/nurmuhammad/e-commerce/backend/src/apps/cart/views.py", line 24, in add_cart
    cart, created = Cart.objects.get_or_create(user=request.user)
  File "/home/nurmuhammad/.local/lib/python3.10/site-packages/django/db/models/manager.py", line 85, in manager_method
    return getattr(self.get_queryset(), name)(*args, **kwargs)
  File "/home/nurmuhammad/.local/lib/python3.10/site-packages/django/db/models/query.py", line 581, in get_or_create
    return self.get(**kwargs), False
  File "/home/nurmuhammad/.local/lib/python3.10/site-packages/django/db/models/query.py", line 431, in get
    num = len(clone)
  File "/home/nurmuhammad/.local/lib/python3.10/site-packages/django/db/models/query.py", line 262, in __len__
    self._fetch_all()
  File "/home/nurmuhammad/.local/lib/python3.10/site-packages/django/db/models/query.py", line 1324, in _fetch_all
    self._result_cache = list(self._iterable_class(self))
  File "/home/nurmuhammad/.local/lib/python3.10/site-packages/django/db/models/query.py", line 51, in __iter__
    results = compiler.execute_sql(chunked_fetch=self.chunked_fetch, chunk_size=self.chunk_size)
  File "/home/nurmuhammad/.local/lib/python3.10/site-packages/django/db/models/sql/compiler.py", line 1175, in execute_sql
    cursor.execute(sql, params)
  File "/home/nurmuhammad/.local/lib/python3.10/site-packages/django/db/backends/utils.py", line 98, in execute
    return super().execute(sql, params)
  File "/home/nurmuhammad/.local/lib/python3.10/site-packages/django/db/backends/utils.py", line 66, in execute
    return self._execute_with_wrappers(sql, params, many=False, executor=self._execute)
  File "/home/nurmuhammad/.local/lib/python3.10/site-packages/django/db/backends/utils.py", line 75, in _execute_with_wrappers
    return executor(sql, params, many, context)
  File "/home/nurmuhammad/.local/lib/python3.10/site-packages/django/db/backends/utils.py", line 79, in _execute
    with self.db.wrap_database_errors:
  File "/home/nurmuhammad/.local/lib/python3.10/site-packages/django/db/utils.py", line 90, in __exit__
    raise dj_exc_value.with_traceback(traceback) from exc_value
  File "/home/nurmuhammad/.local/lib/python3.10/site-packages/django/db/backends/utils.py", line 84, in _execute
    return self.cursor.execute(sql, params)
  File "/home/nurmuhammad/.local/lib/python3.10/site-packages/django/db/backends/sqlite3/base.py", line 423, in execute
    return Database.Cursor.execute(self, query, params)
django.db.utils.OperationalError: no such table: cart_cart
2023-02-14 17:08:00,212 django.request ERROR    Internal Server Error: /store/cat-2/trainers/
Traceback (most recent call last):
  File "/home/nurmuhammad/.local/lib/python3.10/site-packages/django/template/base.py", line 470, in parse
    compile_func = self.tags[command]
KeyError: 'review.user.username'

During handling of the above exception, another exception occurred:

Traceback (most recent call last):
  File "/home/nurmuhammad/.local/lib/python3.10/site-packages/django/core/handlers/exception.py", line 47, in inner
    response = get_response(request)
  File "/home/nurmuhammad/.local/lib/python3.10/site-packages/django/core/handlers/base.py", line 181, in _get_response
    response = wrapped_callback(request, *callback_args, **callback_kwargs)
  File "/home/nurmuhammad/e-commerce/backend/src/apps/store/views/product.py", line 51, in product_detail_view
    return render(request, "store/product_detail.html", context)
  File "/home/nurmuhammad/.local/lib/python3.10/site-packages/django/shortcuts.py", line 19, in render
    content = loader.render_to_string(template_name, context, request, using=using)
  File "/home/nurmuhammad/.local/lib/python3.10/site-packages/django/template/loader.py", line 61, in render_to_string
    template = get_template(template_name, using=using)
  File "/home/nurmuhammad/.local/lib/python3.10/site-packages/django/template/loader.py", line 15, in get_template
    return engine.get_template(template_name)
  File "/home/nurmuhammad/.local/lib/python3.10/site-packages/django/template/backends/django.py", line 34, in get_template
    return Template(self.engine.get_template(template_name), self)
  File "/home/nurmuhammad/.local/lib/python3.10/site-packages/django/template/engine.py", line 143, in get_template
    template, origin = self.find_template(template_name)
  File "/home/nurmuhammad/.local/lib/python3.10/site-packages/django/template/engine.py", line 125, in find_template
    template = loader.get_template(name, skip=skip)
  File "/home/nurmuhammad/.local/lib/python3.10/site-packages/django/template/loaders/base.py", line 29, in get_template
    return Template(
  File "/home/nurmuhammad/.local/lib/python3.10/site-packages/django/template/base.py", line 155, in __init__
    self.nodelist = self.compile_nodelist()
  File "/home/nurmuhammad/.local/lib/python3.10/site-packages/django/template/base.py", line 193, in compile_nodelist
    return parser.parse()
  File "/home/nurmuhammad/.local/lib/python3.10/site-packages/django/template/base.py", line 478, in parse
    raise self.error(token, e)
  File "/home/nurmuhammad/.local/lib/python3.10/site-packages/django/template/base.py", line 476, in parse
    compiled_result = compile_func(self, token)
  File "/home/nurmuhammad/.local/lib/python3.10/site-packages/django/template/loader_tags.py", line 278, in do_extends
    nodelist = parser.parse()
  File "/home/nurmuhammad/.local/lib/python3.10/site-packages/django/template/base.py", line 478, in parse
    raise self.error(token, e)
  File "/home/nurmuhammad/.local/lib/python3.10/site-packages/django/template/base.py", line 476, in parse
    compiled_result = compile_func(self, token)
  File "/home/nurmuhammad/.local/lib/python3.10/site-packages/django/template/loader_tags.py", line 216, in do_block
    nodelist = parser.parse(('endblock',))
  File "/home/nurmuhammad/.local/lib/python3.10/site-packages/django/template/base.py", line 478, in parse
    raise self.error(token, e)
  File "/home/nurmuhammad/.local/lib/python3.10/site-packages/django/template/base.py", line 476, in parse
    compiled_result = compile_func(self, token)
  File "/home/nurmuhammad/.local/lib/python3.10/site-packages/django/template/defaulttags.py", line 817, in do_for
    nodelist_loop = parser.parse(('empty', 'endfor',))
  File "/home/nurmuhammad/.local/lib/python3.10/site-packages/django/template/base.py", line 472, in parse
    self.invalid_block_tag(token, command, parse_until)
  File "/home/nurmuhammad/.local/lib/python3.10/site-packages/django/template/base.py", line 522, in invalid_block_tag
    raise self.error(
django.template.exceptions.TemplateSyntaxError: Invalid block tag on line 211: 'review.user.username', expected 'empty' or 'endfor'. Did you forget to register or load this tag?
